Workbook

Sheet Lun
A1: PdV | B1: 0289 PAM PD ASPETTI | E1: data | F1: 46027 | G1: nr. Carico | I1: 283 | M1: Tot. Val. Copertina Invio | O1: =+C6+I6+O6+U6 -> 20.4 | P1: Tot. Val. Copertina Reso | R1: =F6+L6+R6+X6 -> 4.8 | S1: Valore Carico Copertina | U1: =O1-R1 -> 15.6 | W1: Sett. | X1: 2
A2: 205 CHIMINELLI | G2: "Fornitore" | M2: "Fornitore" | S2: "Fornitore"
B3: n° copie | C3: TOTALE INVIO | E3: n° copie | F3: TOTALE RESO | H3: n° copie | I3: TOTALE INVIO | K3: n° copie | L3: TOTALE RESO | N3: n° copie | O3: TOTALE INVIO | Q3: n° copie | R3: TOTALE RESO | T3: n° copie | U3: TOTALE INVIO | W3: n° copie | X3: TOTALE RESO
A4: Q | B4: =SUM(A9:A33) -> 17 | C4: =SUM(C9:C33) -> 20.4 | D4: Q | E4: =SUM(D9:D33) -> 4 | F4: =SUM(F9:F33) -> 4.8 | G4: Q | H4: =SUM(G9:G33) -> 0 | I4: =SUM(I9:I33) -> 0 | J4: Q | K4: =SUM(J9:J33) -> 0 | L4: =SUM(L9:L33) -> 0 | M4: Q | N4: =SUM(M9:M33) -> 0 | O4: =SUM(O9:O33) -> 0 | P4: Q | Q4: =SUM(P9:P33) -> 0 | R4: =SUM(R9:R33) -> 0 | S4: Q | T4: =SUM(S9:S33) -> 0 | U4: =SUM(U9:U33) -> 0 | V4: Q | W4: =SUM(V9:V33) -> 0 | X4: =SUM(X9:X33) -> 0
A5: P | B5: =SUM(A36:A90) -> 0 | C5: =SUM(C36:C90) -> 0 | D5: P | E5: =SUM(D36:D90) -> 0 | F5: =SUM(F36:F90) -> 0 | G5: P | H5: =SUM(G36:G90) -> 0 | I5: =SUM(I36:I90) -> 0 | J5: P | K5: =SUM(J36:J90) -> 0 | L5: =SUM(L36:L90) -> 0 | M5: P | N5: =SUM(M36:M90) -> 0 | O5: =SUM(O36:O90) -> 0 | P5: P | Q5: =SUM(P36:P90) -> 0 | R5: =SUM(R36:R90) -> 0 | S5: P | T5: =SUM(S36:S90) -> 0 | U5: =SUM(U36:U90) -> 0 | V5: P | W5: =SUM(V36:V90) -> 0 | X5: =SUM(X36:X90) -> 0
C6: =SUM(C4:C5) -> 20.4 | F6: =SUM(F4:F5) -> 4.8 | I6: =SUM(I4:I5) -> 0 | L6: =SUM(L4:L5) -> 0 | O6: =SUM(O4:O5) -> 0 | R6: =SUM(R4:R5) -> 0 | U6: =SUM(U4:U5) -> 0 | X6: =SUM(X4:X5) -> 0
A7: INVIO QUOTIDIANI | D7: RESO QUOTIDIANI | G7: INVIO QUOTIDIANI | J7: RESO QUOTIDIANI | M7: INVIO QUOTIDIANI | P7: RESO QUOTIDIANI | S7: INVIO QUOTIDIANI | V7: RESO QUOTIDIANI
A8: Pezzi | B8: Prezzo | C8: TOTALE | D8: Pezzi | E8: Prezzo | F8: TOTALE | G8: Pezzi | H8: Prezzo | I8: TOTALE | J8: Pezzi | K8: Prezzo | L8: TOTALE | M8: Pezzi | N8: Prezzo | O8: TOTALE | P8: Pezzi | Q8: Prezzo | R8: TOTALE | S8: Pezzi | T8: Prezzo | U8: TOTALE | V8: Pezzi | W8: Prezzo | X8: TOTALE
A9: 17 | B9: 1.2 | C9: =A9*B9 -> 20.4 | D9: 4 | E9: =B9 -> 1.2 | F9: =D9*E9 -> 4.8 | I9: =G9*H9 -> 0 | L9: =J9*K9 -> 0 | O9: =M9*N9 -> 0 | R9: =P9*Q9 -> 0 | U9: =S9*T9 -> 0 | X9: =V9*W9 -> 0
C10: =A10*B10 -> 0 | E10: =B10 -> 0 | F10: =D10*E10 -> 0 | I10: =G10*H10 -> 0 | L10: =J10*K10 -> 0 | O10: =M10*N10 -> 0 | R10: =P10*Q10 -> 0 | U10: =S10*T10 -> 0 | X10: =V10*W10 -> 0
C11: =A11*B11 -> 0 | E11: =B11 -> 0 | F11: =D11*E11 -> 0 | I11: =G11*H11 -> 0 | L11: =J11*K11 -> 0 | O11: =M11*N11 -> 0 | R11: =P11*Q11 -> 0 | U11: =S11*T11 -> 0 | X11: =V11*W11 -> 0
C12: =A12*B12 -> 0 | E12: =B12 -> 0 | F12: =D12*E12 -> 0 | I12: =G12*H12 -> 0 | L12: =J12*K12 -> 0 | O12: =M12*N12 -> 0 | R12: =P12*Q12 -> 0 | U12: =S12*T12 -> 0 | X12: =V12*W12 -> 0
C13: =A13*B13 -> 0 | E13: =B13 -> 0 | F13: =D13*E13 -> 0 | I13: =G13*H13 -> 0 | L13: =J13*K13 -> 0 | O13: =M13*N13 -> 0 | R13: =P13*Q13 -> 0 | U13: =S13*T13 -> 0 | X13: =V13*W13 -> 0
C14: =A14*B14 -> 0 | E14: =B14 -> 0 | F14: =D14*E14 -> 0 | I14: =G14*H14 -> 0 | L14: =J14*K14 -> 0 | O14: =M14*N14 -> 0 | R14: =P14*Q14 -> 0 | U14: =S14*T14 -> 0 | X14: =V14*W14 -> 0
C15: =A15*B15 -> 0 | E15: =B15 -> 0 | F15: =D15*E15 -> 0 | I15: =G15*H15 -> 0 | L15: =J15*K15 -> 0 | O15: =M15*N15 -> 0 | R15: =P15*Q15 -> 0 | U15: =S15*T15 -> 0 | X15: =V15*W15 -> 0
C16: =A16*B16 -> 0 | E16: =B16 -> 0 | F16: =D16*E16 -> 0 | I16: =G16*H16 -> 0 | L16: =J16*K16 -> 0 | O16: =M16*N16 -> 0 | R16: =P16*Q16 -> 0 | U16: =S16*T16 -> 0 | X16: =V16*W16 -> 0
C17: =A17*B17 -> 0 | E17: =B17 -> 0 | F17: =D17*E17 -> 0 | I17: =G17*H17 -> 0 | L17: =J17*K17 -> 0 | O17: =M17*N17 -> 0 | R17: =P17*Q17 -> 0 | U17: =S17*T17 -> 0 | X17: =V17*W17 -> 0
C18: =A18*B18 -> 0 | E18: =B18 -> 0 | F18: =D18*E18 -> 0 | I18: =G18*H18 -> 0 | L18: =J18*K18 -> 0 | O18: =M18*N18 -> 0 | R18: =P18*Q18 -> 0 | U18: =S18*T18 -> 0 | X18: =V18*W18 -> 0
C19: =A19*B19 -> 0 | E19: =B19 -> 0 | F19: =D19*E19 -> 0 | I19: =G19*H19 -> 0 | L19: =J19*K19 -> 0 | O19: =M19*N19 -> 0 | R19: =P19*Q19 -> 0 | U19: =S19*T19 -> 0 | X19: =V19*W19 -> 0
C20: =A20*B20 -> 0 | E20: =B20 -> 0 | F20: =D20*E20 -> 0 | I20: =G20*H20 -> 0 | L20: =J20*K20 -> 0 | O20: =M20*N20 -> 0 | R20: =P20*Q20 -> 0 | U20: =S20*T20 -> 0 | X20: =V20*W20 -> 0
C21: =A21*B21 -> 0 | E21: =B21 -> 0 | F21: =D21*E21 -> 0 | I21: =G21*H21 -> 0 | L21: =J21*K21 -> 0 | O21: =M21*N21 -> 0 | R21: =P21*Q21 -> 0 | U21: =S21*T21 -> 0 | X21: =V21*W21 -> 0
... C33: =A33*B33 -> 0 | E33: =B33 -> 0 | F33: =D33*E33 -> 0 | I33: =G33*H33 -> 0 | L33: =J33*K33 -> 0 | O33: =M33*N33 -> 0 | R33: =P33*Q33 -> 0 | U33: =S33*T33 -> 0 | X33: =V33*W33 -> 0
A34: INVIO RIVISTE | D34: RESO RIVISTE | G34: INVIO RIVISTE | J34: RESO RIVISTE | M34: INVIO RIVISTE | P34: RESO RIVISTE | S34: INVIO RIVISTE | V34: RESO RIVISTE
A35: Pezzi | B35: Prezzo | C35: TOTALE | D35: Pezzi | E35: Prezzo | F35: TOTALE | G35: Pezzi | H35: Prezzo | I35: TOTALE | J35: Pezzi | K35: Prezzo | L35: TOTALE | M35: Pezzi | N35: Prezzo | O35: TOTALE | P35: Pezzi | Q35: Prezzo | R35: TOTALE | S35: Pezzi | T35: Prezzo | U35: TOTALE | V35: Pezzi | W35: Prezzo | X35: TOTALE
C36: =A36*B36 -> 0 | E36: =B36 -> 0 | F36: =D36*E36 -> 0 | I36: =G36*H36 -> 0 | L36: =J36*K36 -> 0 | O36: =M36*N36 -> 0 | R36: =P36*Q36 -> 0 | U36: =S36*T36 -> 0 | X36: =V36*W36 -> 0
C37: =A37*B37 -> 0 | E37: =B37 -> 0 | F37: =D37*E37 -> 0 | I37: =G37*H37 -> 0 | L37: =J37*K37 -> 0 | O37: =M37*N37 -> 0 | R37: =P37*Q37 -> 0 | U37: =S37*T37 -> 0 | X37: =V37*W37 -> 0
C38: =A38*B38 -> 0 | E38: =B38 -> 0 | F38: =D38*E38 -> 0 | I38: =G38*H38 -> 0 | L38: =J38*K38 -> 0 | O38: =M38*N38 -> 0 | R38: =P38*Q38 -> 0 | U38: =S38*T38 -> 0 | X38: =V38*W38 -> 0
C39: =A39*B39 -> 0 | E39: =B39 -> 0 | F39: =D39*E39 -> 0 | I39: =G39*H39 -> 0 | L39: =J39*K39 -> 0 | O39: =M39*N39 -> 0 | R39: =P39*Q39 -> 0 | U39: =S39*T39 -> 0 | X39: =V39*W39 -> 0
C40: =A40*B40 -> 0 | E40: =B40 -> 0 | F40: =D40*E40 -> 0 | I40: =G40*H40 -> 0 | L40: =J40*K40 -> 0 | O40: =M40*N40 -> 0 | R40: =P40*Q40 -> 0 | U40: =S40*T40 -> 0 | X40: =V40*W40 -> 0
C41: =A41*B41 -> 0 | E41: =B41 -> 0 | F41: =D41*E41 -> 0 | I41: =G41*H41 -> 0 | L41: =J41*K41 -> 0 | O41: =M41*N41 -> 0 | R41: =P41*Q41 -> 0 | U41: =S41*T41 -> 0 | X41: =V41*W41 -> 0
C42: =A42*B42 -> 0 | E42: =B42 -> 0 | F42: =D42*E42 -> 0 | I42: =G42*H42 -> 0 | L42: =J42*K42 -> 0 | O42: =M42*N42 -> 0 | R42: =P42*Q42 -> 0 | U42: =S42*T42 -> 0 | X42: =V42*W42 -> 0
C43: =A43*B43 -> 0 | E43: =B43 -> 0 | F43: =D43*E43 -> 0 | I43: =G43*H43 -> 0 | L43: =J43*K43 -> 0 | O43: =M43*N43 -> 0 | R43: =P43*Q43 -> 0 | U43: =S43*T43 -> 0 | X43: =V43*W43 -> 0
C44: =A44*B44 -> 0 | E44: =B44 -> 0 | F44: =D44*E44 -> 0 | I44: =G44*H44 -> 0 | L44: =J44*K44 -> 0 | O44: =M44*N44 -> 0 | R44: =P44*Q44 -> 0 | U44: =S44*T44 -> 0 | X44: =V44*W44 -> 0
C45: =A45*B45 -> 0 | E45: =B45 -> 0 | F45: =D45*E45 -> 0 | I45: =G45*H45 -> 0 | L45: =J45*K45 -> 0 | O45: =M45*N45 -> 0 | R45: =P45*Q45 -> 0 | U45: =S45*T45 -> 0 | X45: =V45*W45 -> 0
C46: =A46*B46 -> 0 | E46: =B46 -> 0 | F46: =D46*E46 -> 0 | I46: =G46*H46 -> 0 | L46: =J46*K46 -> 0 | O46: =M46*N46 -> 0 | R46: =P46*Q46 -> 0 | U46: =S46*T46 -> 0 | X46: =V46*W46 -> 0
C47: =A47*B47 -> 0 | E47: =B47 -> 0 | F47: =D47*E47 -> 0 | I47: =G47*H47 -> 0 | L47: =J47*K47 -> 0 | O47: =M47*N47 -> 0 | R47: =P47*Q47 -> 0 | U47: =S47*T47 -> 0 | X47: =V47*W47 -> 0
... C60: =A60*B60 -> 0 | E60: =B60 -> 0 | F60: =D60*E60 -> 0 | I60: =G60*H60 -> 0 | L60: =J60*K60 -> 0 | O60: =M60*N60 -> 0 | R60: =P60*Q60 -> 0 | U60: =S60*T60 -> 0 | X60: =V60*W60 -> 0
C61: =A61*B61 -> 0 | F61: =D61*E61 -> 0 | I61: =G61*H61 -> 0 | L61: =J61*K61 -> 0 | O61: =M61*N61 -> 0 | R61: =P61*Q61 -> 0 | U61: =S61*T61 -> 0 | X61: =V61*W61 -> 0
C62: =A62*B62 -> 0 | F62: =D62*E62 -> 0 | I62: =G62*H62 -> 0 | L62: =J62*K62 -> 0 | O62: =M62*N62 -> 0 | R62: =P62*Q62 -> 0 | U62: =S62*T62 -> 0 | X62: =V62*W62 -> 0
C63: =A63*B63 -> 0 | F63: =D63*E63 -> 0 | I63: =G63*H63 -> 0 | L63: =J63*K63 -> 0 | O63: =M63*N63 -> 0 | R63: =P63*Q63 -> 0 | U63: =S63*T63 -> 0 | X63: =V63*W63 -> 0
...

Sheet Mar
A1: PdV | B1: 0289 PAM PD ASPETTI | E1: data | F1: =Lun!F1+1 -> 46028 | G1: nr. Carico | I1: =Lun!I1+1 -> 284 | M1: Tot. Val. Copertina Invio | O1: =+C6+I6+O6+U6 -> 0 | P1: Tot. Val. Copertina Reso | R1: =F6+L6+R6+X6 -> 0 | S1: Valore Carico Copertina | U1: =O1-R1 -> 0 | W1: Sett. | X1: =Lun!X1 -> 2
A2: 205 CHIMINELLI | G2: "Fornitore" | M2: "Fornitore" | S2: "Fornitore"
B3: n° copie | C3: TOTALE INVIO | E3: n° copie | F3: TOTALE RESO | H3: n° copie | I3: TOTALE INVIO | K3: n° copie | L3: TOTALE RESO | N3: n° copie | O3: TOTALE INVIO | Q3: n° copie | R3: TOTALE RESO | T3: n° copie | U3: TOTALE INVIO | W3: n° copie | X3: TOTALE RESO
A4: Q | B4: =SUM(A9:A33) -> 0 | C4: =SUM(C9:C33) -> 0 | D4: Q | E4: =SUM(D9:D33) -> 0 | F4: =SUM(F9:F33) -> 0 | G4: Q | H4: =SUM(G9:G33) -> 0 | I4: =SUM(I9:I33) -> 0 | J4: Q | K4: =SUM(J9:J33) -> 0 | L4: =SUM(L9:L33) -> 0 | M4: Q | N4: =SUM(M9:M33) -> 0 | O4: =SUM(O9:O33) -> 0 | P4: Q | Q4: =SUM(P9:P33) -> 0 | R4: =SUM(R9:R33) -> 0 | S4: Q | T4: =SUM(S9:S33) -> 0 | U4: =SUM(U9:U33) -> 0 | V4: Q | W4: =SUM(V9:V33) -> 0 | X4: =SUM(X9:X33) -> 0
A5: P | B5: =SUM(A36:A90) -> 0 | C5: =SUM(C36:C90) -> 0 | D5: P | E5: =SUM(D36:D90) -> 0 | F5: =SUM(F36:F90) -> 0 | G5: P | H5: =SUM(G36:G90) -> 0 | I5: =SUM(I36:I90) -> 0 | J5: P | K5: =SUM(J36:J90) -> 0 | L5: =SUM(L36:L90) -> 0 | M5: P | N5: =SUM(M36:M90) -> 0 | O5: =SUM(O36:O90) -> 0 | P5: P | Q5: =SUM(P36:P90) -> 0 | R5: =SUM(R36:R90) -> 0 | S5: P | T5: =SUM(S36:S90) -> 0 | U5: =SUM(U36:U90) -> 0 | V5: P | W5: =SUM(V36:V90) -> 0 | X5: =SUM(X36:X90) -> 0
C6: =SUM(C4:C5) -> 0 | F6: =SUM(F4:F5) -> 0 | I6: =SUM(I4:I5) -> 0 | L6: =SUM(L4:L5) -> 0 | O6: =SUM(O4:O5) -> 0 | R6: =SUM(R4:R5) -> 0 | U6: =SUM(U4:U5) -> 0 | X6: =SUM(X4:X5) -> 0
A7: INVIO QUOTIDIANI | D7: RESO QUOTIDIANI | G7: INVIO QUOTIDIANI | J7: RESO QUOTIDIANI | M7: INVIO QUOTIDIANI | P7: RESO QUOTIDIANI | S7: INVIO QUOTIDIANI | V7: RESO QUOTIDIANI
A8: Pezzi | B8: Prezzo | C8: TOTALE | D8: Pezzi | E8: Prezzo | F8: TOTALE | G8: Pezzi | H8: Prezzo | I8: TOTALE | J8: Pezzi | K8: Prezzo | L8: TOTALE | M8: Pezzi | N8: Prezzo | O8: TOTALE | P8: Pezzi | Q8: Prezzo | R8: TOTALE | S8: Pezzi | T8: Prezzo | U8: TOTALE | V8: Pezzi | W8: Prezzo | X8: TOTALE
C9: =A9*B9 -> 0 | E9: =B9 -> 0 | F9: =D9*E9 -> 0 | I9: =G9*H9 -> 0 | L9: =J9*K9 -> 0 | O9: =M9*N9 -> 0 | R9: =P9*Q9 -> 0 | U9: =S9*T9 -> 0 | X9: =V9*W9 -> 0
C10: =A10*B10 -> 0 | E10: =B10 -> 0 | F10: =D10*E10 -> 0 | I10: =G10*H10 -> 0 | L10: =J10*K10 -> 0 | O10: =M10*N10 -> 0 | R10: =P10*Q10 -> 0 | U10: =S10*T10 -> 0 | X10: =V10*W10 -> 0
C11: =A11*B11 -> 0 | E11: =B11 -> 0 | F11: =D11*E11 -> 0 | I11: =G11*H11 -> 0 | L11: =J11*K11 -> 0 | O11: =M11*N11 -> 0 | R11: =P11*Q11 -> 0 | U11: =S11*T11 -> 0 | X11: =V11*W11 -> 0
C12: =A12*B12 -> 0 | E12: =B12 -> 0 | F12: =D12*E12 -> 0 | I12: =G12*H12 -> 0 | L12: =J12*K12 -> 0 | O12: =M12*N12 -> 0 | R12: =P12*Q12 -> 0 | U12: =S12*T12 -> 0 | X12: =V12*W12 -> 0
C13: =A13*B13 -> 0 | E13: =B13 -> 0 | F13: =D13*E13 -> 0 | I13: =G13*H13 -> 0 | L13: =J13*K13 -> 0 | O13: =M13*N13 -> 0 | R13: =P13*Q13 -> 0 | U13: =S13*T13 -> 0 | X13: =V13*W13 -> 0
C14: =A14*B14 -> 0 | E14: =B14 -> 0 | F14: =D14*E14 -> 0 | I14: =G14*H14 -> 0 | L14: =J14*K14 -> 0 | O14: =M14*N14 -> 0 | R14: =P14*Q14 -> 0 | U14: =S14*T14 -> 0 | X14: =V14*W14 -> 0
C15: =A15*B15 -> 0 | E15: =B15 -> 0 | F15: =D15*E15 -> 0 | I15: =G15*H15 -> 0 | L15: =J15*K15 -> 0 | O15: =M15*N15 -> 0 | R15: =P15*Q15 -> 0 | U15: =S15*T15 -> 0 | X15: =V15*W15 -> 0
C16: =A16*B16 -> 0 | E16: =B16 -> 0 | F16: =D16*E16 -> 0 | I16: =G16*H16 -> 0 | L16: =J16*K16 -> 0 | O16: =M16*N16 -> 0 | R16: =P16*Q16 -> 0 | U16: =S16*T16 -> 0 | X16: =V16*W16 -> 0
C17: =A17*B17 -> 0 | E17: =B17 -> 0 | F17: =D17*E17 -> 0 | I17: =G17*H17 -> 0 | L17: =J17*K17 -> 0 | O17: =M17*N17 -> 0 | R17: =P17*Q17 -> 0 | U17: =S17*T17 -> 0 | X17: =V17*W17 -> 0
C18: =A18*B18 -> 0 | E18: =B18 -> 0 | F18: =D18*E18 -> 0 | I18: =G18*H18 -> 0 | L18: =J18*K18 -> 0 | O18: =M18*N18 -> 0 | R18: =P18*Q18 -> 0 | U18: =S18*T18 -> 0 | X18: =V18*W18 -> 0
C19: =A19*B19 -> 0 | E19: =B19 -> 0 | F19: =D19*E19 -> 0 | I19: =G19*H19 -> 0 | L19: =J19*K19 -> 0 | O19: =M19*N19 -> 0 | R19: =P19*Q19 -> 0 | U19: =S19*T19 -> 0 | X19: =V19*W19 -> 0
C20: =A20*B20 -> 0 | E20: =B20 -> 0 | F20: =D20*E20 -> 0 | I20: =G20*H20 -> 0 | L20: =J20*K20 -> 0 | O20: =M20*N20 -> 0 | R20: =P20*Q20 -> 0 | U20: =S20*T20 -> 0 | X20: =V20*W20 -> 0
... C22: =A22*B22 -> 0 | E22: =B22 -> 0 | F22: =D22*E22 -> 0 | I22: =G22*H22 -> 0 | L22: =J22*K22 -> 0 | O22: =M22*N22 -> 0 | R22: =P22*Q22 -> 0 | U22: =S22*T22 -> 0 | X22: =V22*W22 -> 0
C23: =A50*B23 -> 0 | E23: =B23 -> 0 | F23: =D23*E23 -> 0 | I23: =G23*H23 -> 0 | L23: =J23*K23 -> 0 | O23: =M23*N23 -> 0 | R23: =P23*Q23 -> 0 | U23: =S23*T23 -> 0 | X23: =V23*W23 -> 0
C24: =A51*B24 -> 0 | E24: =B24 -> 0 | F24: =D24*E24 -> 0 | I24: =G24*H24 -> 0 | L24: =J24*K24 -> 0 | O24: =M24*N24 -> 0 | R24: =P24*Q24 -> 0 | U24: =S24*T24 -> 0 | X24: =V24*W24 -> 0
C25: =A52*B25 -> 0 | E25: =B25 -> 0 | F25: =D25*E25 -> 0 | I25: =G25*H25 -> 0 | L25: =J25*K25 -> 0 | O25: =M25*N25 -> 0 | R25: =P25*Q25 -> 0 | U25: =S25*T25 -> 0 | X25: =V25*W25 -> 0
C26: =A53*B26 -> 0 | E26: =B26 -> 0 | F26: =D26*E26 -> 0 | I26: =G26*H26 -> 0 | L26: =J26*K26 -> 0 | O26: =M26*N26 -> 0 | R26: =P26*Q26 -> 0 | U26: =S26*T26 -> 0 | X26: =V26*W26 -> 0
C27: =A54*B27 -> 0 | E27: =B27 -> 0 | F27: =D27*E27 -> 0 | I27: =G27*H27 -> 0 | L27: =J27*K27 -> 0 | O27: =M27*N27 -> 0 | R27: =P27*Q27 -> 0 | U27: =S27*T27 -> 0 | X27: =V27*W27 -> 0
C28: =A55*B28 -> 0 | E28: =B28 -> 0 | F28: =D28*E28 -> 0 | I28: =G28*H28 -> 0 | L28: =J28*K28 -> 0 | O28: =M28*N28 -> 0 | R28: =P28*Q28 -> 0 | U28: =S28*T28 -> 0 | X28: =V28*W28 -> 0
C29: =A56*B29 -> 0 | E29: =B29 -> 0 | F29: =D29*E29 -> 0 | I29: =G29*H29 -> 0 | L29: =J29*K29 -> 0 | O29: =M29*N29 -> 0 | R29: =P29*Q29 -> 0 | U29: =S29*T29 -> 0 | X29: =V29*W29 -> 0
C30: =A57*B30 -> 0 | E30: =B30 -> 0 | F30: =D30*E30 -> 0 | I30: =G30*H30 -> 0 | L30: =J30*K30 -> 0 | O30: =M30*N30 -> 0 | R30: =P30*Q30 -> 0 | U30: =S30*T30 -> 0 | X30: =V30*W30 -> 0
C31: =A58*B31 -> 0 | E31: =B31 -> 0 | F31: =D31*E31 -> 0 | I31: =G31*H31 -> 0 | L31: =J31*K31 -> 0 | O31: =M31*N31 -> 0 | R31: =P31*Q31 -> 0 | U31: =S31*T31 -> 0 | X31: =V31*W31 -> 0
C32: =A59*B32 -> 0 | E32: =B32 -> 0 | F32: =D32*E32 -> 0 | I32: =G32*H32 -> 0 | L32: =J32*K32 -> 0 | O32: =M32*N32 -> 0 | R32: =P32*Q32 -> 0 | U32: =S32*T32 -> 0 | X32: =V32*W32 -> 0
C33: =A60*B33 -> 0 | E33: =B33 -> 0 | F33: =D33*E33 -> 0 | I33: =G33*H33 -> 0 | L33: =J33*K33 -> 0 | O33: =M33*N33 -> 0 | R33: =P33*Q33 -> 0 | U33: =S33*T33 -> 0 | X33: =V33*W33 -> 0
A34: 6 | D34: RESO RIVISTE | G34: INVIO RIVISTE | J34: RESO RIVISTE | M34: INVIO RIVISTE | P34: RESO RIVISTE | S34: INVIO RIVISTE | V34: RESO RIVISTE
A35: Pezzi | B35: Prezzo | C35: TOTALE | D35: Pezzi | E35: Prezzo | F35: TOTALE | G35: Pezzi | H35: Prezzo | I35: TOTALE | J35: Pezzi | K35: Prezzo | L35: TOTALE | M35: Pezzi | N35: Prezzo | O35: TOTALE | P35: Pezzi | Q35: Prezzo | R35: TOTALE | S35: Pezzi | T35: Prezzo | U35: TOTALE | V35: Pezzi | W35: Prezzo | X35: TOTALE
C36: =A36*B36 -> 0 | E36: =B36 -> 0 | F36: =D36*E36 -> 0 | I36: =G36*H36 -> 0 | L36: =J36*K36 -> 0 | O36: =M36*N36 -> 0 | R36: =P36*Q36 -> 0 | U36: =S36*T36 -> 0 | X36: =V36*W36 -> 0
C37: =A37*B37 -> 0 | E37: =B37 -> 0 | F37: =D37*E37 -> 0 | I37: =G37*H37 -> 0 | L37: =J37*K37 -> 0 | O37: =M37*N37 -> 0 | R37: =P37*Q37 -> 0 | U37: =S37*T37 -> 0 | X37: =V37*W37 -> 0
C38: =A38*B38 -> 0 | E38: =B38 -> 0 | F38: =D38*E38 -> 0 | I38: =G38*H38 -> 0 | L38: =J38*K38 -> 0 | O38: =M38*N38 -> 0 | R38: =P38*Q38 -> 0 | U38: =S38*T38 -> 0 | X38: =V38*W38 -> 0
C39: =A39*B39 -> 0 | E39: =B39 -> 0 | F39: =D39*E39 -> 0 | I39: =G39*H39 -> 0 | L39: =J39*K39 -> 0 | O39: =M39*N39 -> 0 | R39: =P39*Q39 -> 0 | U39: =S39*T39 -> 0 | X39: =V39*W39 -> 0
C40: =A40*B40 -> 0 | E40: =B40 -> 0 | F40: =D40*E40 -> 0 | I40: =G40*H40 -> 0 | L40: =J40*K40 -> 0 | O40: =M40*N40 -> 0 | R40: =P40*Q40 -> 0 | U40: =S40*T40 -> 0 | X40: =V40*W40 -> 0
C41: =A41*B41 -> 0 | E41: =B41 -> 0 | F41: =D41*E41 -> 0 | I41: =G41*H41 -> 0 | L41: =J41*K41 -> 0 | O41: =M41*N41 -> 0 | R41: =P41*Q41 -> 0 | U41: =S41*T41 -> 0 | X41: =V41*W41 -> 0
...

Sheet Mer
A1: PdV | B1: 0289 PAM PD ASPETTI | E1: data | F1: =Lun!F1+2 -> 46029 | G1: nr. Carico | I1: =Lun!I1+2 -> 285 | M1: Tot. Val. Copertina Invio | O1: =+C6+I6+O6+U6 -> 0 | P1: Tot. Val. Copertina Reso | R1: =F6+L6+R6+X6 -> 0 | S1: Valore Carico Copertina | U1: =O1-R1 -> 0 | W1: Sett. | X1: =Lun!X1 -> 2
A2: 205 CHIMINELLI | G2: "Fornitore" | M2: "Fornitore" | S2: "Fornitore"
B3: n° copie | C3: TOTALE INVIO | E3: n° copie | F3: TOTALE RESO | H3: n° copie | I3: TOTALE INVIO | K3: n° copie | L3: TOTALE RESO | N3: n° copie | O3: TOTALE INVIO | Q3: n° copie | R3: TOTALE RESO | T3: n° copie | U3: TOTALE INVIO | W3: n° copie | X3: TOTALE RESO
A4: Q | B4: =SUM(A9:A33) -> 0 | C4: =SUM(C9:C33) -> 0 | D4: Q | E4: =SUM(D9:D33) -> 0 | F4: =SUM(F9:F33) -> 0 | G4: Q | H4: =SUM(G9:G33) -> 0 | I4: =SUM(I9:I33) -> 0 | J4: Q | K4: =SUM(J9:J33) -> 0 | L4: =SUM(L9:L33) -> 0 | M4: Q | N4: =SUM(M9:M33) -> 0 | O4: =SUM(O9:O33) -> 0 | P4: Q | Q4: =SUM(P9:P33) -> 0 | R4: =SUM(R9:R33) -> 0 | S4: Q | T4: =SUM(S9:S33) -> 0 | U4: =SUM(U9:U33) -> 0 | V4: Q | W4: =SUM(V9:V33) -> 0 | X4: =SUM(X9:X33) -> 0
A5: P | B5: =SUM(A36:A90) -> 0 | C5: =SUM(C36:C90) -> 0 | D5: P | E5: =SUM(D36:D90) -> 0 | F5: =SUM(F36:F90) -> 0 | G5: P | H5: =SUM(G36:G90) -> 0 | I5: =SUM(I36:I90) -> 0 | J5: P | K5: =SUM(J36:J90) -> 0 | L5: =SUM(L36:L90) -> 0 | M5: P | N5: =SUM(M36:M90) -> 0 | O5: =SUM(O36:O90) -> 0 | P5: P | Q5: =SUM(P36:P90) -> 0 | R5: =SUM(R36:R90) -> 0 | S5: P | T5: =SUM(S36:S90) -> 0 | U5: =SUM(U36:U90) -> 0 | V5: P | W5: =SUM(V36:V90) -> 0 | X5: =SUM(X36:X90) -> 0
C6: =SUM(C4:C5) -> 0 | F6: =SUM(F4:F5) -> 0 | I6: =SUM(I4:I5) -> 0 | L6: =SUM(L4:L5) -> 0 | O6: =SUM(O4:O5) -> 0 | R6: =SUM(R4:R5) -> 0 | U6: =SUM(U4:U5) -> 0 | X6: =SUM(X4:X5) -> 0
A7: INVIO QUOTIDIANI | D7: RESO QUOTIDIANI | G7: INVIO QUOTIDIANI | J7: RESO QUOTIDIANI | M7: INVIO QUOTIDIANI | P7: RESO QUOTIDIANI | S7: INVIO QUOTIDIANI | V7: RESO QUOTIDIANI
A8: Pezzi | B8: Prezzo | C8: TOTALE | D8: Pezzi | E8: Prezzo | F8: TOTALE | G8: Pezzi | H8: Prezzo | I8: TOTALE | J8: Pezzi | K8: Prezzo | L8: TOTALE | M8: Pezzi | N8: Prezzo | O8: TOTALE | P8: Pezzi | Q8: Prezzo | R8: TOTALE | S8: Pezzi | T8: Prezzo | U8: TOTALE | V8: Pezzi | W8: Prezzo | X8: TOTALE
C9: =A9*B9 -> 0 | E9: =B9 -> 0 | F9: =D9*E9 -> 0 | I9: =G9*H9 -> 0 | L9: =J9*K9 -> 0 | O9: =M9*N9 -> 0 | R9: =P9*Q9 -> 0 | U9: =S9*T9 -> 0 | X9: =V9*W9 -> 0
C10: =A10*B10 -> 0 | E10: =B10 -> 0 | F10: =D10*E10 -> 0 | I10: =G10*H10 -> 0 | L10: =J10*K10 -> 0 | O10: =M10*N10 -> 0 | R10: =P10*Q10 -> 0 | U10: =S10*T10 -> 0 | X10: =V10*W10 -> 0
C11: =A11*B11 -> 0 | E11: =B11 -> 0 | F11: =D11*E11 -> 0 | I11: =G11*H11 -> 0 | L11: =J11*K11 -> 0 | O11: =M11*N11 -> 0 | R11: =P11*Q11 -> 0 | U11: =S11*T11 -> 0 | X11: =V11*W11 -> 0
C12: =A12*B12 -> 0 | E12: =B12 -> 0 | F12: =D12*E12 -> 0 | I12: =G12*H12 -> 0 | L12: =J12*K12 -> 0 | O12: =M12*N12 -> 0 | R12: =P12*Q12 -> 0 | U12: =S12*T12 -> 0 | X12: =V12*W12 -> 0
C13: =A13*B13 -> 0 | E13: =B13 -> 0 | F13: =D13*E13 -> 0 | I13: =G13*H13 -> 0 | L13: =J13*K13 -> 0 | O13: =M13*N13 -> 0 | R13: =P13*Q13 -> 0 | U13: =S13*T13 -> 0 | X13: =V13*W13 -> 0
C14: =A14*B14 -> 0 | E14: =B14 -> 0 | F14: =D14*E14 -> 0 | I14: =G14*H14 -> 0 | L14: =J14*K14 -> 0 | O14: =M14*N14 -> 0 | R14: =P14*Q14 -> 0 | U14: =S14*T14 -> 0 | X14: =V14*W14 -> 0
C15: =A15*B15 -> 0 | E15: =B15 -> 0 | F15: =D15*E15 -> 0 | I15: =G15*H15 -> 0 | L15: =J15*K15 -> 0 | O15: =M15*N15 -> 0 | R15: =P15*Q15 -> 0 | U15: =S15*T15 -> 0 | X15: =V15*W15 -> 0
C16: =A16*B16 -> 0 | E16: =B16 -> 0 | F16: =D16*E16 -> 0 | I16: =G16*H16 -> 0 | L16: =J16*K16 -> 0 | O16: =M16*N16 -> 0 | R16: =P16*Q16 -> 0 | U16: =S16*T16 -> 0 | X16: =V16*W16 -> 0
C17: =A17*B17 -> 0 | E17: =B17 -> 0 | F17: =D17*E17 -> 0 | I17: =G17*H17 -> 0 | L17: =J17*K17 -> 0 | O17: =M17*N17 -> 0 | R17: =P17*Q17 -> 0 | U17: =S17*T17 -> 0 | X17: =V17*W17 -> 0
C18: =A18*B18 -> 0 | E18: =B18 -> 0 | F18: =D18*E18 -> 0 | I18: =G18*H18 -> 0 | L18: =J18*K18 -> 0 | O18: =M18*N18 -> 0 | R18: =P18*Q18 -> 0 | U18: =S18*T18 -> 0 | X18: =V18*W18 -> 0
C19: =A19*B19 -> 0 | E19: =B19 -> 0 | F19: =D19*E19 -> 0 | I19: =G19*H19 -> 0 | L19: =J19*K19 -> 0 | O19: =M19*N19 -> 0 | R19: =P19*Q19 -> 0 | U19: =S19*T19 -> 0 | X19: =V19*W19 -> 0
C20: =A20*B20 -> 0 | E20: =B20 -> 0 | F20: =D20*E20 -> 0 | I20: =G20*H20 -> 0 | L20: =J20*K20 -> 0 | O20: =M20*N20 -> 0 | R20: =P20*Q20 -> 0 | U20: =S20*T20 -> 0 | X20: =V20*W20 -> 0
... C33: =A33*B33 -> 0 | E33: =B33 -> 0 | F33: =D33*E33 -> 0 | I33: =G33*H33 -> 0 | L33: =J33*K33 -> 0 | O33: =M33*N33 -> 0 | R33: =P33*Q33 -> 0 | U33: =S33*T33 -> 0 | X33: =V33*W33 -> 0
A34: INVIO RIVISTE | D34: RESO RIVISTE | G34: INVIO RIVISTE | J34: RESO RIVISTE | M34: INVIO RIVISTE | P34: RESO RIVISTE | S34: INVIO RIVISTE | V34: RESO RIVISTE
A35: Pezzi | B35: Prezzo | C35: TOTALE | D35: Pezzi | E35: Prezzo | F35: TOTALE | G35: Pezzi | H35: Prezzo | I35: TOTALE | J35: Pezzi | K35: Prezzo | L35: TOTALE | M35: Pezzi | N35: Prezzo | O35: TOTALE | P35: Pezzi | Q35: Prezzo | R35: TOTALE | S35: Pezzi | T35: Prezzo | U35: TOTALE | V35: Pezzi | W35: Prezzo | X35: TOTALE
C36: =A36*B36 -> 0 | E36: =B36 -> 0 | F36: =D36*E36 -> 0 | I36: =G36*H36 -> 0 | L36: =J36*K36 -> 0 | O36: =M36*N36 -> 0 | R36: =P36*Q36 -> 0 | U36: =S36*T36 -> 0 | X36: =V36*W36 -> 0
C37: =A37*B37 -> 0 | E37: =B37 -> 0 | F37: =D37*E37 -> 0 | I37: =G37*H37 -> 0 | L37: =J37*K37 -> 0 | O37: =M37*N37 -> 0 | R37: =P37*Q37 -> 0 | U37: =S37*T37 -> 0 | X37: =V37*W37 -> 0
C38: =A38*B38 -> 0 | E38: =B38 -> 0 | F38: =D38*E38 -> 0 | I38: =G38*H38 -> 0 | L38: =J38*K38 -> 0 | O38: =M38*N38 -> 0 | R38: =P38*Q38 -> 0 | U38: =S38*T38 -> 0 | X38: =V38*W38 -> 0
C39: =A39*B39 -> 0 | E39: =B39 -> 0 | F39: =D39*E39 -> 0 | I39: =G39*H39 -> 0 | L39: =J39*K39 -> 0 | O39: =M39*N39 -> 0 | R39: =P39*Q39 -> 0 | U39: =S39*T39 -> 0 | X39: =V39*W39 -> 0
C40: =A40*B40 -> 0 | E40: =B40 -> 0 | F40: =D40*E40 -> 0 | I40: =G40*H40 -> 0 | L40: =J40*K40 -> 0 | O40: =M40*N40 -> 0 | R40: =P40*Q40 -> 0 | U40: =S40*T40 -> 0 | X40: =V40*W40 -> 0
C41: =A41*B41 -> 0 | E41: =B41 -> 0 | F41: =D41*E41 -> 0 | I41: =G41*H41 -> 0 | L41: =J41*K41 -> 0 | O41: =M41*N41 -> 0 | R41: =P41*Q41 -> 0 | U41: =S41*T41 -> 0 | X41: =V41*W41 -> 0
C42: =A42*B42 -> 0 | E42: =B42 -> 0 | F42: =D42*E42 -> 0 | I42: =G42*H42 -> 0 | L42: =J42*K42 -> 0 | O42: =M42*N42 -> 0 | R42: =P42*Q42 -> 0 | U42: =S42*T42 -> 0 | X42: =V42*W42 -> 0
C43: =A43*B43 -> 0 | E43: =B43 -> 0 | F43: =D43*E43 -> 0 | I43: =G43*H43 -> 0 | L43: =J43*K43 -> 0 | O43: =M43*N43 -> 0 | R43: =P43*Q43 -> 0 | U43: =S43*T43 -> 0 | X43: =V43*W43 -> 0
C44: =A44*B44 -> 0 | E44: =B44 -> 0 | F44: =D44*E44 -> 0 | I44: =G44*H44 -> 0 | L44: =J44*K44 -> 0 | O44: =M44*N44 -> 0 | R44: =P44*Q44 -> 0 | U44: =S44*T44 -> 0 | X44: =V44*W44 -> 0
C45: =A45*B45 -> 0 | E45: =B45 -> 0 | F45: =D45*E45 -> 0 | I45: =G45*H45 -> 0 | L45: =J45*K45 -> 0 | O45: =M45*N45 -> 0 | R45: =P45*Q45 -> 0 | U45: =S45*T45 -> 0 | X45: =V45*W45 -> 0
C46: =A46*B46 -> 0 | E46: =B46 -> 0 | F46: =D46*E46 -> 0 | I46: =G46*H46 -> 0 | L46: =J46*K46 -> 0 | O46: =M46*N46 -> 0 | R46: =P46*Q46 -> 0 | U46: =S46*T46 -> 0 | X46: =V46*W46 -> 0
C47: =A47*B47 -> 0 | E47: =B47 -> 0 | F47: =D47*E47 -> 0 | I47: =G47*H47 -> 0 | L47: =J47*K47 -> 0 | O47: =M47*N47 -> 0 | R47: =P47*Q47 -> 0 | U47: =S47*T47 -> 0 | X47: =V47*W47 -> 0
... C90: =A90*B90 -> 0 | E90: =B90 -> 0 | F90: =D90*E90 -> 0 | I90: =G90*H90 -> 0 | L90: =J90*K90 -> 0 | O90: =M90*N90 -> 0 | R90: =P90*Q90 -> 0 | U90: =S90*T90 -> 0 | X90: =V90*W90 -> 0
A93: Q | B93: Quotidiani
A94: P | B94: Riviste

Sheet Gio
A1: PdV | B1: 0289 PAM PD ASPETTI | E1: data | F1: =Lun!F1+3 -> 46030 | G1: nr. Carico | I1: =Lun!I1+3 -> 286 | M1: Tot. Val. Copertina Invio | O1: =+C6+I6+O6+U6 -> 0 | P1: Tot. Val. Copertina Reso | R1: =F6+L6+R6+X6 -> 0 | S1: Valore Carico Copertina | U1: =O1-R1 -> 0 | W1: Sett. | X1: =Lun!X1 -> 2
A2: 205 CHIMINELLI | G2: "Fornitore" | M2: "Fornitore" | S2: "Fornitore"
B3: n° copie | C3: TOTALE INVIO | E3: n° copie | F3: TOTALE RESO | H3: n° copie | I3: TOTALE INVIO | K3: n° copie | L3: TOTALE RESO | N3: n° copie | O3: TOTALE INVIO | Q3: n° copie | R3: TOTALE RESO | T3: n° copie | U3: TOTALE INVIO | W3: n° copie | X3: TOTALE RESO
A4: Q | B4: =SUM(A9:A33) -> 0 | C4: =SUM(C9:C33) -> 0 | D4: Q | E4: =SUM(D9:D33) -> 0 | F4: =SUM(F9:F33) -> 0 | G4: Q | H4: =SUM(G9:G33) -> 0 | I4: =SUM(I9:I33) -> 0 | J4: Q | K4: =SUM(J9:J33) -> 0 | L4: =SUM(L9:L33) -> 0 | M4: Q | N4: =SUM(M9:M33) -> 0 | O4: =SUM(O9:O33) -> 0 | P4: Q | Q4: =SUM(P9:P33) -> 0 | R4: =SUM(R9:R33) -> 0 | S4: Q | T4: =SUM(S9:S33) -> 0 | U4: =SUM(U9:U33) -> 0 | V4: Q | W4: =SUM(V9:V33) -> 0 | X4: =SUM(X9:X33) -> 0
A5: P | B5: =SUM(A36:A90) -> 0 | C5: =SUM(C36:C90) -> 0 | D5: P | E5: =SUM(D36:D90) -> 0 | F5: =SUM(F36:F90) -> 0 | G5: P | H5: =SUM(G36:G90) -> 0 | I5: =SUM(I36:I90) -> 0 | J5: P | K5: =SUM(J36:J90) -> 0 | L5: =SUM(L36:L90) -> 0 | M5: P | N5: =SUM(M36:M90) -> 0 | O5: =SUM(O36:O90) -> 0 | P5: P | Q5: =SUM(P36:P90) -> 0 | R5: =SUM(R36:R90) -> 0 | S5: P | T5: =SUM(S36:S90) -> 0 | U5: =SUM(U36:U90) -> 0 | V5: P | W5: =SUM(V36:V90) -> 0 | X5: =SUM(X36:X90) -> 0
C6: =SUM(C4:C5) -> 0 | F6: =SUM(F4:F5) -> 0 | I6: =SUM(I4:I5) -> 0 | L6: =SUM(L4:L5) -> 0 | O6: =SUM(O4:O5) -> 0 | R6: =SUM(R4:R5) -> 0 | U6: =SUM(U4:U5) -> 0 | X6: =SUM(X4:X5) -> 0
A7: INVIO QUOTIDIANI | D7: RESO QUOTIDIANI | G7: INVIO QUOTIDIANI | J7: RESO QUOTIDIANI | M7: INVIO QUOTIDIANI | P7: RESO QUOTIDIANI | S7: INVIO QUOTIDIANI | V7: RESO QUOTIDIANI
A8: Pezzi | B8: Prezzo | C8: TOTALE | D8: Pezzi | E8: Prezzo | F8: TOTALE | G8: Pezzi | H8: Prezzo | I8: TOTALE | J8: Pezzi | K8: Prezzo | L8: TOTALE | M8: Pezzi | N8: Prezzo | O8: TOTALE | P8: Pezzi | Q8: Prezzo | R8: TOTALE | S8: Pezzi | T8: Prezzo | U8: TOTALE | V8: Pezzi | W8: Prezzo | X8: TOTALE
C9: =A9*B9 -> 0 | E9: =B9 -> 0 | F9: =D9*E9 -> 0 | I9: =G9*H9 -> 0 | L9: =J9*K9 -> 0 | O9: =M9*N9 -> 0 | R9: =P9*Q9 -> 0 | U9: =S9*T9 -> 0 | X9: =V9*W9 -> 0
C10: =A10*B10 -> 0 | E10: =B10 -> 0 | F10: =D10*E10 -> 0 | I10: =G10*H10 -> 0 | L10: =J10*K10 -> 0 | O10: =M10*N10 -> 0 | R10: =P10*Q10 -> 0 | U10: =S10*T10 -> 0 | X10: =V10*W10 -> 0
C11: =A11*B11 -> 0 | E11: =B11 -> 0 | F11: =D11*E11 -> 0 | I11: =G11*H11 -> 0 | L11: =J11*K11 -> 0 | O11: =M11*N11 -> 0 | R11: =P11*Q11 -> 0 | U11: =S11*T11 -> 0 | X11: =V11*W11 -> 0
C12: =A12*B12 -> 0 | E12: =B12 -> 0 | F12: =D12*E12 -> 0 | I12: =G12*H12 -> 0 | L12: =J12*K12 -> 0 | O12: =M12*N12 -> 0 | R12: =P12*Q12 -> 0 | U12: =S12*T12 -> 0 | X12: =V12*W12 -> 0
C13: =A13*B13 -> 0 | E13: =B13 -> 0 | F13: =D13*E13 -> 0 | I13: =G13*H13 -> 0 | L13: =J13*K13 -> 0 | O13: =M13*N13 -> 0 | R13: =P13*Q13 -> 0 | U13: =S13*T13 -> 0 | X13: =V13*W13 -> 0
C14: =A14*B14 -> 0 | E14: =B14 -> 0 | F14: =D14*E14 -> 0 | I14: =G14*H14 -> 0 | L14: =J14*K14 -> 0 | O14: =M14*N14 -> 0 | R14: =P14*Q14 -> 0 | U14: =S14*T14 -> 0 | X14: =V14*W14 -> 0
C15: =A15*B15 -> 0 | E15: =B15 -> 0 | F15: =D15*E15 -> 0 | I15: =G15*H15 -> 0 | L15: =J15*K15 -> 0 | O15: =M15*N15 -> 0 | R15: =P15*Q15 -> 0 | U15: =S15*T15 -> 0 | X15: =V15*W15 -> 0
C16: =A16*B16 -> 0 | E16: =B16 -> 0 | F16: =D16*E16 -> 0 | I16: =G16*H16 -> 0 | L16: =J16*K16 -> 0 | O16: =M16*N16 -> 0 | R16: =P16*Q16 -> 0 | U16: =S16*T16 -> 0 | X16: =V16*W16 -> 0
C17: =A17*B17 -> 0 | E17: =B17 -> 0 | F17: =D17*E17 -> 0 | I17: =G17*H17 -> 0 | L17: =J17*K17 -> 0 | O17: =M17*N17 -> 0 | R17: =P17*Q17 -> 0 | U17: =S17*T17 -> 0 | X17: =V17*W17 -> 0
C18: =A18*B18 -> 0 | E18: =B18 -> 0 | F18: =D18*E18 -> 0 | I18: =G18*H18 -> 0 | L18: =J18*K18 -> 0 | O18: =M18*N18 -> 0 | R18: =P18*Q18 -> 0 | U18: =S18*T18 -> 0 | X18: =V18*W18 -> 0
C19: =A19*B19 -> 0 | E19: =B19 -> 0 | F19: =D19*E19 -> 0 | I19: =G19*H19 -> 0 | L19: =J19*K19 -> 0 | O19: =M19*N19 -> 0 | R19: =P19*Q19 -> 0 | U19: =S19*T19 -> 0 | X19: =V19*W19 -> 0
C20: =A20*B20 -> 0 | E20: =B20 -> 0 | F20: =D20*E20 -> 0 | I20: =G20*H20 -> 0 | L20: =J20*K20 -> 0 | O20: =M20*N20 -> 0 | R20: =P20*Q20 -> 0 | U20: =S20*T20 -> 0 | X20: =V20*W20 -> 0
... C33: =A33*B33 -> 0 | E33: =B33 -> 0 | F33: =D33*E33 -> 0 | I33: =G33*H33 -> 0 | L33: =J33*K33 -> 0 | O33: =M33*N33 -> 0 | R33: =P33*Q33 -> 0 | U33: =S33*T33 -> 0 | X33: =V33*W33 -> 0
A34: INVIO RIVISTE | D34: RESO RIVISTE | G34: INVIO RIVISTE | J34: RESO RIVISTE | M34: INVIO RIVISTE | P34: RESO RIVISTE | S34: INVIO RIVISTE | V34: RESO RIVISTE
A35: Pezzi | B35: Prezzo | C35: TOTALE | D35: Pezzi | E35: Prezzo | F35: TOTALE | G35: Pezzi | H35: Prezzo | I35: TOTALE | J35: Pezzi | K35: Prezzo | L35: TOTALE | M35: Pezzi | N35: Prezzo | O35: TOTALE | P35: Pezzi | Q35: Prezzo | R35: TOTALE | S35: Pezzi | T35: Prezzo | U35: TOTALE | V35: Pezzi | W35: Prezzo | X35: TOTALE
C36: =A36*B36 -> 0 | E36: =B36 -> 0 | F36: =D36*E36 -> 0 | I36: =G36*H36 -> 0 | L36: =J36*K36 -> 0 | O36: =M36*N36 -> 0 | R36: =P36*Q36 -> 0 | U36: =S36*T36 -> 0 | X36: =V36*W36 -> 0
C37: =A37*B37 -> 0 | E37: =B37 -> 0 | F37: =D37*E37 -> 0 | I37: =G37*H37 -> 0 | L37: =J37*K37 -> 0 | O37: =M37*N37 -> 0 | R37: =P37*Q37 -> 0 | U37: =S37*T37 -> 0 | X37: =V37*W37 -> 0
C38: =A38*B38 -> 0 | E38: =B38 -> 0 | F38: =D38*E38 -> 0 | I38: =G38*H38 -> 0 | L38: =J38*K38 -> 0 | O38: =M38*N38 -> 0 | R38: =P38*Q38 -> 0 | U38: =S38*T38 -> 0 | X38: =V38*W38 -> 0
C39: =A39*B39 -> 0 | E39: =B39 -> 0 | F39: =D39*E39 -> 0 | I39: =G39*H39 -> 0 | L39: =J39*K39 -> 0 | O39: =M39*N39 -> 0 | R39: =P39*Q39 -> 0 | U39: =S39*T39 -> 0 | X39: =V39*W39 -> 0
C40: =A40*B40 -> 0 | E40: =B40 -> 0 | F40: =D40*E40 -> 0 | I40: =G40*H40 -> 0 | L40: =J40*K40 -> 0 | O40: =M40*N40 -> 0 | R40: =P40*Q40 -> 0 | U40: =S40*T40 -> 0 | X40: =V40*W40 -> 0
C41: =A41*B41 -> 0 | E41: =B41 -> 0 | F41: =D41*E41 -> 0 | I41: =G41*H41 -> 0 | L41: =J41*K41 -> 0 | O41: =M41*N41 -> 0 | R41: =P41*Q41 -> 0 | U41: =S41*T41 -> 0 | X41: =V41*W41 -> 0
C42: =A42*B42 -> 0 | E42: =B42 -> 0 | F42: =D42*E42 -> 0 | I42: =G42*H42 -> 0 | L42: =J42*K42 -> 0 | O42: =M42*N42 -> 0 | R42: =P42*Q42 -> 0 | U42: =S42*T42 -> 0 | X42: =V42*W42 -> 0
C43: =A43*B43 -> 0 | E43: =B43 -> 0 | F43: =D43*E43 -> 0 | I43: =G43*H43 -> 0 | L43: =J43*K43 -> 0 | O43: =M43*N43 -> 0 | R43: =P43*Q43 -> 0 | U43: =S43*T43 -> 0 | X43: =V43*W43 -> 0
C44: =A44*B44 -> 0 | E44: =B44 -> 0 | F44: =D44*E44 -> 0 | I44: =G44*H44 -> 0 | L44: =J44*K44 -> 0 | O44: =M44*N44 -> 0 | R44: =P44*Q44 -> 0 | U44: =S44*T44 -> 0 | X44: =V44*W44 -> 0
C45: =A45*B45 -> 0 | E45: =B45 -> 0 | F45: =D45*E45 -> 0 | I45: =G45*H45 -> 0 | L45: =J45*K45 -> 0 | O45: =M45*N45 -> 0 | R45: =P45*Q45 -> 0 | U45: =S45*T45 -> 0 | X45: =V45*W45 -> 0
C46: =A46*B46 -> 0 | E46: =B46 -> 0 | F46: =D46*E46 -> 0 | I46: =G46*H46 -> 0 | L46: =J46*K46 -> 0 | O46: =M46*N46 -> 0 | R46: =P46*Q46 -> 0 | U46: =S46*T46 -> 0 | X46: =V46*W46 -> 0
C47: =A47*B47 -> 0 | E47: =B47 -> 0 | F47: =D47*E47 -> 0 | I47: =G47*H47 -> 0 | L47: =J47*K47 -> 0 | O47: =M47*N47 -> 0 | R47: =P47*Q47 -> 0 | U47: =S47*T47 -> 0 | X47: =V47*W47 -> 0
... C60: =A60*B60 -> 0 | E60: =B60 -> 0 | F60: =D60*E60 -> 0 | I60: =G60*H60 -> 0 | L60: =J60*K60 -> 0 | O60: =M60*N60 -> 0 | R60: =P60*Q60 -> 0 | U60: =S60*T60 -> 0 | X60: =V60*W60 -> 0
C61: =A61*B61 -> 0 | E61: 2 | F61: =D61*E61 -> 0 | I61: =G61*H61 -> 0 | L61: =J61*K61 -> 0 | O61: =M61*N61 -> 0 | R61: =P61*Q61 -> 0 | U61: =S61*T61 -> 0 | X61: =V61*W61 -> 0
C62: =A62*B62 -> 0 | E62: =B62 -> 0 | F62: =D62*E62 -> 0 | I62: =G62*H62 -> 0 | L62: =J62*K62 -> 0 | O62: =M62*N62 -> 0 | R62: =P62*Q62 -> 0 | U62: =S62*T62 -> 0 | X62: =V62*W62 -> 0
C63: =A63*B63 -> 0 | E63: =B63 -> 0 | F63: =D63*E63 -> 0 | I63: =G63*H63 -> 0 | L63: =J63*K63 -> 0 | O63: =M63*N63 -> 0 | R63: =P63*Q63 -> 0 | U63: =S63*T63 -> 0 | X63: =V63*W63 -> 0
C64: =A64*B64 -> 0 | E64: =B64 -> 0 | F64: =D64*E64 -> 0 | I64: =G64*H64 -> 0 | L64: =J64*K64 -> 0 | O64: =M64*N64 -> 0 | R64: =P64*Q64 -> 0 | U64: =S64*T64 -> 0 | X64: =V64*W64 -> 0
...

Sheet Ven
A1: PdV | B1: 0289 PAM PD ASPETTI | E1: data | F1: =Lun!F1+4 -> 46031 | G1: nr. Carico | I1: =Lun!I1+4 -> 287 | M1: Tot. Val. Copertina Invio | O1: =+C6+I6+O6+U6 -> 0 | P1: Tot. Val. Copertina Reso | R1: =F6+L6+R6+X6 -> 0 | S1: Valore Carico Copertina | U1: =O1-R1 -> 0 | W1: Sett. | X1: =Lun!X1 -> 2
A2: 205 CHIMINELLI | G2: "Fornitore" | M2: "Fornitore" | S2: "Fornitore"
B3: n° copie | C3: TOTALE INVIO | E3: n° copie | F3: TOTALE RESO | H3: n° copie | I3: TOTALE INVIO | K3: n° copie | L3: TOTALE RESO | N3: n° copie | O3: TOTALE INVIO | Q3: n° copie | R3: TOTALE RESO | T3: n° copie | U3: TOTALE INVIO | W3: n° copie | X3: TOTALE RESO
A4: Q | B4: =SUM(A9:A33) -> 0 | C4: =SUM(C9:C33) -> 0 | D4: Q | E4: =SUM(D9:D33) -> 0 | F4: =SUM(F9:F33) -> 0 | G4: Q | H4: =SUM(G9:G33) -> 0 | I4: =SUM(I9:I33) -> 0 | J4: Q | K4: =SUM(J9:J33) -> 0 | L4: =SUM(L9:L33) -> 0 | M4: Q | N4: =SUM(M9:M33) -> 0 | O4: =SUM(O9:O33) -> 0 | P4: Q | Q4: =SUM(P9:P33) -> 0 | R4: =SUM(R9:R33) -> 0 | S4: Q | T4: =SUM(S9:S33) -> 0 | U4: =SUM(U9:U33) -> 0 | V4: Q | W4: =SUM(V9:V33) -> 0 | X4: =SUM(X9:X33) -> 0
A5: P | B5: =SUM(A36:A90) -> 0 | C5: =SUM(C36:C90) -> 0 | D5: P | E5: =SUM(D36:D90) -> 0 | F5: =SUM(F36:F90) -> 0 | G5: P | H5: =SUM(G36:G90) -> 0 | I5: =SUM(I36:I90) -> 0 | J5: P | K5: =SUM(J36:J90) -> 0 | L5: =SUM(L36:L90) -> 0 | M5: P | N5: =SUM(M36:M90) -> 0 | O5: =SUM(O36:O90) -> 0 | P5: P | Q5: =SUM(P36:P90) -> 0 | R5: =SUM(R36:R90) -> 0 | S5: P | T5: =SUM(S36:S90) -> 0 | U5: =SUM(U36:U90) -> 0 | V5: P | W5: =SUM(V36:V90) -> 0 | X5: =SUM(X36:X90) -> 0
C6: =SUM(C4:C5) -> 0 | F6: =SUM(F4:F5) -> 0 | I6: =SUM(I4:I5) -> 0 | L6: =SUM(L4:L5) -> 0 | O6: =SUM(O4:O5) -> 0 | R6: =SUM(R4:R5) -> 0 | U6: =SUM(U4:U5) -> 0 | X6: =SUM(X4:X5) -> 0
A7: INVIO QUOTIDIANI | D7: RESO QUOTIDIANI | G7: INVIO QUOTIDIANI | J7: RESO QUOTIDIANI | M7: INVIO QUOTIDIANI | P7: RESO QUOTIDIANI | S7: INVIO QUOTIDIANI | V7: RESO QUOTIDIANI
A8: Pezzi | B8: Prezzo | C8: TOTALE | D8: Pezzi | E8: Prezzo | F8: TOTALE | G8: Pezzi | H8: Prezzo | I8: TOTALE | J8: Pezzi | K8: Prezzo | L8: TOTALE | M8: Pezzi | N8: Prezzo | O8: TOTALE | P8: Pezzi | Q8: Prezzo | R8: TOTALE | S8: Pezzi | T8: Prezzo | U8: TOTALE | V8: Pezzi | W8: Prezzo | X8: TOTALE
C9: =A9*B9 -> 0 | E9: =B9 -> 0 | F9: =D9*E9 -> 0 | I9: =G9*H9 -> 0 | L9: =J9*K9 -> 0 | O9: =M9*N9 -> 0 | R9: =P9*Q9 -> 0 | U9: =S9*T9 -> 0 | X9: =V9*W9 -> 0
C10: =A10*B10 -> 0 | E10: =B10 -> 0 | F10: =D10*E10 -> 0 | I10: =G10*H10 -> 0 | L10: =J10*K10 -> 0 | O10: =M10*N10 -> 0 | R10: =P10*Q10 -> 0 | U10: =S10*T10 -> 0 | X10: =V10*W10 -> 0
C11: =A11*B11 -> 0 | E11: =B11 -> 0 | F11: =D11*E11 -> 0 | I11: =G11*H11 -> 0 | L11: =J11*K11 -> 0 | O11: =M11*N11 -> 0 | R11: =P11*Q11 -> 0 | U11: =S11*T11 -> 0 | X11: =V11*W11 -> 0
C12: =A12*B12 -> 0 | E12: =B12 -> 0 | F12: =D12*E12 -> 0 | I12: =G12*H12 -> 0 | L12: =J12*K12 -> 0 | O12: =M12*N12 -> 0 | R12: =P12*Q12 -> 0 | U12: =S12*T12 -> 0 | X12: =V12*W12 -> 0
C13: =A13*B13 -> 0 | E13: =B13 -> 0 | F13: =D13*E13 -> 0 | I13: =G13*H13 -> 0 | L13: =J13*K13 -> 0 | O13: =M13*N13 -> 0 | R13: =P13*Q13 -> 0 | U13: =S13*T13 -> 0 | X13: =V13*W13 -> 0
C14: =A14*B14 -> 0 | E14: =B14 -> 0 | F14: =D14*E14 -> 0 | I14: =G14*H14 -> 0 | L14: =J14*K14 -> 0 | O14: =M14*N14 -> 0 | R14: =P14*Q14 -> 0 | U14: =S14*T14 -> 0 | X14: =V14*W14 -> 0
C15: =A15*B15 -> 0 | E15: =B15 -> 0 | F15: =D15*E15 -> 0 | I15: =G15*H15 -> 0 | L15: =J15*K15 -> 0 | O15: =M15*N15 -> 0 | R15: =P15*Q15 -> 0 | U15: =S15*T15 -> 0 | X15: =V15*W15 -> 0
C16: =A16*B16 -> 0 | E16: =B16 -> 0 | F16: =D16*E16 -> 0 | I16: =G16*H16 -> 0 | L16: =J16*K16 -> 0 | O16: =M16*N16 -> 0 | R16: =P16*Q16 -> 0 | U16: =S16*T16 -> 0 | X16: =V16*W16 -> 0
C17: =A17*B17 -> 0 | E17: =B17 -> 0 | F17: =D17*E17 -> 0 | I17: =G17*H17 -> 0 | L17: =J17*K17 -> 0 | O17: =M17*N17 -> 0 | R17: =P17*Q17 -> 0 | U17: =S17*T17 -> 0 | X17: =V17*W17 -> 0
C18: =A18*B18 -> 0 | E18: =B18 -> 0 | F18: =D18*E18 -> 0 | I18: =G18*H18 -> 0 | L18: =J18*K18 -> 0 | O18: =M18*N18 -> 0 | R18: =P18*Q18 -> 0 | U18: =S18*T18 -> 0 | X18: =V18*W18 -> 0
C19: =A19*B19 -> 0 | E19: =B19 -> 0 | F19: =D19*E19 -> 0 | I19: =G19*H19 -> 0 | L19: =J19*K19 -> 0 | O19: =M19*N19 -> 0 | R19: =P19*Q19 -> 0 | U19: =S19*T19 -> 0 | X19: =V19*W19 -> 0
C20: =A20*B20 -> 0 | E20: =B20 -> 0 | F20: =D20*E20 -> 0 | I20: =G20*H20 -> 0 | L20: =J20*K20 -> 0 | O20: =M20*N20 -> 0 | R20: =P20*Q20 -> 0 | U20: =S20*T20 -> 0 | X20: =V20*W20 -> 0
... C33: =A33*B33 -> 0 | E33: =B33 -> 0 | F33: =D33*E33 -> 0 | I33: =G33*H33 -> 0 | L33: =J33*K33 -> 0 | O33: =M33*N33 -> 0 | R33: =P33*Q33 -> 0 | U33: =S33*T33 -> 0 | X33: =V33*W33 -> 0
A34: INVIO RIVISTE | D34: RESO RIVISTE | G34: INVIO RIVISTE | J34: RESO RIVISTE | M34: INVIO RIVISTE | P34: RESO RIVISTE | S34: INVIO RIVISTE | V34: RESO RIVISTE
A35: Pezzi | B35: Prezzo | C35: TOTALE | D35: Pezzi | E35: Prezzo | F35: TOTALE | G35: Pezzi | H35: Prezzo | I35: TOTALE | J35: Pezzi | K35: Prezzo | L35: TOTALE | M35: Pezzi | N35: Prezzo | O35: TOTALE | P35: Pezzi | Q35: Prezzo | R35: TOTALE | S35: Pezzi | T35: Prezzo | U35: TOTALE | V35: Pezzi | W35: Prezzo | X35: TOTALE
C36: =A36*B36 -> 0 | E36: =B36 -> 0 | F36: =D36*E36 -> 0 | I36: =G36*H36 -> 0 | L36: =J36*K36 -> 0 | O36: =M36*N36 -> 0 | R36: =P36*Q36 -> 0 | U36: =S36*T36 -> 0 | X36: =V36*W36 -> 0
C37: =A37*B37 -> 0 | E37: =B37 -> 0 | F37: =D37*E37 -> 0 | I37: =G37*H37 -> 0 | L37: =J37*K37 -> 0 | O37: =M37*N37 -> 0 | R37: =P37*Q37 -> 0 | U37: =S37*T37 -> 0 | X37: =V37*W37 -> 0
C38: =A38*B38 -> 0 | E38: =B38 -> 0 | F38: =D38*E38 -> 0 | I38: =G38*H38 -> 0 | L38: =J38*K38 -> 0 | O38: =M38*N38 -> 0 | R38: =P38*Q38 -> 0 | U38: =S38*T38 -> 0 | X38: =V38*W38 -> 0
C39: =A39*B39 -> 0 | E39: =B39 -> 0 | F39: =D39*E39 -> 0 | I39: =G39*H39 -> 0 | L39: =J39*K39 -> 0 | O39: =M39*N39 -> 0 | R39: =P39*Q39 -> 0 | U39: =S39*T39 -> 0 | X39: =V39*W39 -> 0
C40: =A40*B40 -> 0 | E40: =B40 -> 0 | F40: =D40*E40 -> 0 | I40: =G40*H40 -> 0 | L40: =J40*K40 -> 0 | O40: =M40*N40 -> 0 | R40: =P40*Q40 -> 0 | U40: =S40*T40 -> 0 | X40: =V40*W40 -> 0
C41: =A41*B41 -> 0 | E41: =B41 -> 0 | F41: =D41*E41 -> 0 | I41: =G41*H41 -> 0 | L41: =J41*K41 -> 0 | O41: =M41*N41 -> 0 | R41: =P41*Q41 -> 0 | U41: =S41*T41 -> 0 | X41: =V41*W41 -> 0
C42: =A42*B42 -> 0 | E42: =B42 -> 0 | F42: =D42*E42 -> 0 | I42: =G42*H42 -> 0 | L42: =J42*K42 -> 0 | O42: =M42*N42 -> 0 | R42: =P42*Q42 -> 0 | U42: =S42*T42 -> 0 | X42: =V42*W42 -> 0
C43: =A43*B43 -> 0 | E43: =B43 -> 0 | F43: =D43*E43 -> 0 | I43: =G43*H43 -> 0 | L43: =J43*K43 -> 0 | O43: =M43*N43 -> 0 | R43: =P43*Q43 -> 0 | U43: =S43*T43 -> 0 | X43: =V43*W43 -> 0
C44: =A44*B44 -> 0 | E44: =B44 -> 0 | F44: =D44*E44 -> 0 | I44: =G44*H44 -> 0 | L44: =J44*K44 -> 0 | O44: =M44*N44 -> 0 | R44: =P44*Q44 -> 0 | U44: =S44*T44 -> 0 | X44: =V44*W44 -> 0
C45: =A45*B45 -> 0 | E45: =B45 -> 0 | F45: =D45*E45 -> 0 | I45: =G45*H45 -> 0 | L45: =J45*K45 -> 0 | O45: =M45*N45 -> 0 | R45: =P45*Q45 -> 0 | U45: =S45*T45 -> 0 | X45: =V45*W45 -> 0
C46: =A46*B46 -> 0 | E46: =B46 -> 0 | F46: =D46*E46 -> 0 | I46: =G46*H46 -> 0 | L46: =J46*K46 -> 0 | O46: =M46*N46 -> 0 | R46: =P46*Q46 -> 0 | U46: =S46*T46 -> 0 | X46: =V46*W46 -> 0
C47: =A47*B47 -> 0 | E47: =B47 -> 0 | F47: =D47*E47 -> 0 | I47: =G47*H47 -> 0 | L47: =J47*K47 -> 0 | O47: =M47*N47 -> 0 | R47: =P47*Q47 -> 0 | U47: =S47*T47 -> 0 | X47: =V47*W47 -> 0
... C67: =A67*B67 -> 0 | E67: =B67 -> 0 | F67: =D67*E67 -> 0 | I67: =G67*H67 -> 0 | L67: =J67*K67 -> 0 | O67: =M67*N67 -> 0 | R67: =P67*Q67 -> 0 | U67: =S67*T67 -> 0 | X67: =V67*W67 -> 0
C68: =A68*B68 -> 0 | F68: =D68*E68 -> 0 | I68: =G68*H68 -> 0 | L68: =J68*K68 -> 0 | O68: =M68*N68 -> 0 | R68: =P68*Q68 -> 0 | U68: =S68*T68 -> 0 | X68: =V68*W68 -> 0
C69: =A69*B69 -> 0 | F69: =D69*E69 -> 0 | I69: =G69*H69 -> 0 | L69: =J69*K69 -> 0 | O69: =M69*N69 -> 0 | R69: =P69*Q69 -> 0 | U69: =S69*T69 -> 0 | X69: =V69*W69 -> 0
C70: =A70*B70 -> 0 | F70: =D70*E70 -> 0 | I70: =G70*H70 -> 0 | L70: =J70*K70 -> 0 | O70: =M70*N70 -> 0 | R70: =P70*Q70 -> 0 | U70: =S70*T70 -> 0 | X70: =V70*W70 -> 0
C71: =A71*B71 -> 0 | F71: =D71*E71 -> 0 | I71: =G71*H71 -> 0 | L71: =J71*K71 -> 0 | O71: =M71*N71 -> 0 | R71: =P71*Q71 -> 0 | U71: =S71*T71 -> 0 | X71: =V71*W71 -> 0
...

Sheet Sab
A1: PdV | B1: 0289 PAM PD ASPETTI | E1: data | F1: =Lun!F1+5 -> 46032 | G1: nr. Carico | I1: 282 | M1: Tot. Val. Copertina Invio | O1: =+C6+I6+O6+U6 -> 0 | P1: Tot. Val. Copertina Reso | R1: =F6+L6+R6+X6 -> 0 | S1: Valore Carico Copertina | U1: =O1-R1 -> 0 | W1: Sett. | X1: =Lun!X1 -> 2
A2: 205 CHIMINELLI | G2: "Fornitore" | M2: "Fornitore" | S2: "Fornitore"
B3: n° copie | C3: TOTALE INVIO | E3: n° copie | F3: TOTALE RESO | H3: n° copie | I3: TOTALE INVIO | K3: n° copie | L3: TOTALE RESO | N3: n° copie | O3: TOTALE INVIO | Q3: n° copie | R3: TOTALE RESO | T3: n° copie | U3: TOTALE INVIO | W3: n° copie | X3: TOTALE RESO
A4: Q | B4: =SUM(A9:A33) -> 0 | C4: =SUM(C9:C33) -> 0 | D4: Q | E4: =SUM(D9:D33) -> 0 | F4: =SUM(F9:F33) -> 0 | G4: Q | H4: =SUM(G9:G33) -> 0 | I4: =SUM(I9:I33) -> 0 | J4: Q | K4: =SUM(J9:J33) -> 0 | L4: =SUM(L9:L33) -> 0 | M4: Q | N4: =SUM(M9:M33) -> 0 | O4: =SUM(O9:O33) -> 0 | P4: Q | Q4: =SUM(P9:P33) -> 0 | R4: =SUM(R9:R33) -> 0 | S4: Q | T4: =SUM(S9:S33) -> 0 | U4: =SUM(U9:U33) -> 0 | V4: Q | W4: =SUM(V9:V33) -> 0 | X4: =SUM(X9:X33) -> 0
A5: P | B5: =SUM(A36:A91) -> 0 | C5: =SUM(C36:C91) -> 0 | D5: P | E5: =SUM(D36:D91) -> 0 | F5: =SUM(F36:F91) -> 0 | G5: P | H5: =SUM(G36:G91) -> 0 | I5: =SUM(I36:I91) -> 0 | J5: P | K5: =SUM(J36:J91) -> 0 | L5: =SUM(L36:L91) -> 0 | M5: P | N5: =SUM(M36:M91) -> 0 | O5: =SUM(O36:O91) -> 0 | P5: P | Q5: =SUM(P36:P91) -> 0 | R5: =SUM(R36:R91) -> 0 | S5: P | T5: =SUM(S36:S91) -> 0 | U5: =SUM(U36:U91) -> 0 | V5: P | W5: =SUM(V36:V91) -> 0 | X5: =SUM(X36:X91) -> 0
C6: =SUM(C4:C5) -> 0 | F6: =SUM(F4:F5) -> 0 | I6: =SUM(I4:I5) -> 0 | L6: =SUM(L4:L5) -> 0 | O6: =SUM(O4:O5) -> 0 | R6: =SUM(R4:R5) -> 0 | U6: =SUM(U4:U5) -> 0 | X6: =SUM(X4:X5) -> 0
A7: INVIO QUOTIDIANI | D7: RESO QUOTIDIANI | G7: INVIO QUOTIDIANI | J7: RESO QUOTIDIANI | M7: INVIO QUOTIDIANI | P7: RESO QUOTIDIANI | S7: INVIO QUOTIDIANI | V7: RESO QUOTIDIANI
A8: Pezzi | B8: Prezzo | C8: TOTALE | D8: Pezzi | E8: Prezzo | F8: TOTALE | G8: Pezzi | H8: Prezzo | I8: TOTALE | J8: Pezzi | K8: Prezzo | L8: TOTALE | M8: Pezzi | N8: Prezzo | O8: TOTALE | P8: Pezzi | Q8: Prezzo | R8: TOTALE | S8: Pezzi | T8: Prezzo | U8: TOTALE | V8: Pezzi | W8: Prezzo | X8: TOTALE
C9: =A9*B9 -> 0 | E9: =B9 -> 0 | F9: =D9*E9 -> 0 | I9: =G9*H9 -> 0 | L9: =J9*K9 -> 0 | O9: =M9*N9 -> 0 | R9: =P9*Q9 -> 0 | U9: =S9*T9 -> 0 | X9: =V9*W9 -> 0
C10: =A10*B10 -> 0 | E10: =B10 -> 0 | F10: =D10*E10 -> 0 | I10: =G10*H10 -> 0 | L10: =J10*K10 -> 0 | O10: =M10*N10 -> 0 | R10: =P10*Q10 -> 0 | U10: =S10*T10 -> 0 | X10: =V10*W10 -> 0
C11: =A11*B11 -> 0 | E11: =B11 -> 0 | F11: =D11*E11 -> 0 | I11: =G11*H11 -> 0 | L11: =J11*K11 -> 0 | O11: =M11*N11 -> 0 | R11: =P11*Q11 -> 0 | U11: =S11*T11 -> 0 | X11: =V11*W11 -> 0
C12: =A12*B12 -> 0 | E12: =B12 -> 0 | F12: =D12*E12 -> 0 | I12: =G12*H12 -> 0 | L12: =J12*K12 -> 0 | O12: =M12*N12 -> 0 | R12: =P12*Q12 -> 0 | U12: =S12*T12 -> 0 | X12: =V12*W12 -> 0
C13: =A13*B13 -> 0 | E13: =B13 -> 0 | F13: =D13*E13 -> 0 | I13: =G13*H13 -> 0 | L13: =J13*K13 -> 0 | O13: =M13*N13 -> 0 | R13: =P13*Q13 -> 0 | U13: =S13*T13 -> 0 | X13: =V13*W13 -> 0
C14: =A14*B14 -> 0 | E14: =B14 -> 0 | F14: =D14*E14 -> 0 | I14: =G14*H14 -> 0 | L14: =J14*K14 -> 0 | O14: =M14*N14 -> 0 | R14: =P14*Q14 -> 0 | U14: =S14*T14 -> 0 | X14: =V14*W14 -> 0
C15: =A15*B15 -> 0 | E15: =B15 -> 0 | F15: =D15*E15 -> 0 | I15: =G15*H15 -> 0 | L15: =J15*K15 -> 0 | O15: =M15*N15 -> 0 | R15: =P15*Q15 -> 0 | U15: =S15*T15 -> 0 | X15: =V15*W15 -> 0
C16: =A16*B16 -> 0 | E16: =B16 -> 0 | F16: =D16*E16 -> 0 | I16: =G16*H16 -> 0 | L16: =J16*K16 -> 0 | O16: =M16*N16 -> 0 | R16: =P16*Q16 -> 0 | U16: =S16*T16 -> 0 | X16: =V16*W16 -> 0
C17: =A17*B17 -> 0 | E17: =B17 -> 0 | F17: =D17*E17 -> 0 | I17: =G17*H17 -> 0 | L17: =J17*K17 -> 0 | O17: =M17*N17 -> 0 | R17: =P17*Q17 -> 0 | U17: =S17*T17 -> 0 | X17: =V17*W17 -> 0
C18: =A18*B18 -> 0 | E18: =B18 -> 0 | F18: =D18*E18 -> 0 | I18: =G18*H18 -> 0 | L18: =J18*K18 -> 0 | O18: =M18*N18 -> 0 | R18: =P18*Q18 -> 0 | U18: =S18*T18 -> 0 | X18: =V18*W18 -> 0
C19: =A19*B19 -> 0 | E19: =B19 -> 0 | F19: =D19*E19 -> 0 | I19: =G19*H19 -> 0 | L19: =J19*K19 -> 0 | O19: =M19*N19 -> 0 | R19: =P19*Q19 -> 0 | U19: =S19*T19 -> 0 | X19: =V19*W19 -> 0
C20: =A20*B20 -> 0 | E20: =B20 -> 0 | F20: =D20*E20 -> 0 | I20: =G20*H20 -> 0 | L20: =J20*K20 -> 0 | O20: =M20*N20 -> 0 | R20: =P20*Q20 -> 0 | U20: =S20*T20 -> 0 | X20: =V20*W20 -> 0
... C33: =A33*B33 -> 0 | E33: =B33 -> 0 | F33: =D33*E33 -> 0 | I33: =G33*H33 -> 0 | L33: =J33*K33 -> 0 | O33: =M33*N33 -> 0 | R33: =P33*Q33 -> 0 | U33: =S33*T33 -> 0 | X33: =V33*W33 -> 0
A34: INVIO RIVISTE | D34: RESO RIVISTE | G34: INVIO RIVISTE | J34: RESO RIVISTE | M34: INVIO RIVISTE | P34: RESO RIVISTE | S34: INVIO RIVISTE | V34: RESO RIVISTE
A35: Pezzi | B35: Prezzo | C35: TOTALE | D35: Pezzi | E35: Prezzo | F35: TOTALE | G35: Pezzi | H35: Prezzo | I35: TOTALE | J35: Pezzi | K35: Prezzo | L35: TOTALE | M35: Pezzi | N35: Prezzo | O35: TOTALE | P35: Pezzi | Q35: Prezzo | R35: TOTALE | S35: Pezzi | T35: Prezzo | U35: TOTALE | V35: Pezzi | W35: Prezzo | X35: TOTALE
C36: =A36*B36 -> 0 | E36: =B36 -> 0 | F36: =D36*E36 -> 0 | I36: =G36*H36 -> 0 | L36: =J36*K36 -> 0 | O36: =M36*N36 -> 0 | R36: =P36*Q36 -> 0 | U36: =S36*T36 -> 0 | X36: =V36*W36 -> 0
C37: =A37*B37 -> 0 | E37: =B37 -> 0 | F37: =D37*E37 -> 0 | I37: =G37*H37 -> 0 | L37: =J37*K37 -> 0 | O37: =M37*N37 -> 0 | R37: =P37*Q37 -> 0 | U37: =S37*T37 -> 0 | X37: =V37*W37 -> 0
C38: =A38*B38 -> 0 | E38: =B38 -> 0 | F38: =D38*E38 -> 0 | I38: =G38*H38 -> 0 | L38: =J38*K38 -> 0 | O38: =M38*N38 -> 0 | R38: =P38*Q38 -> 0 | U38: =S38*T38 -> 0 | X38: =V38*W38 -> 0
C39: =A39*B39 -> 0 | E39: =B39 -> 0 | F39: =D39*E39 -> 0 | I39: =G39*H39 -> 0 | L39: =J39*K39 -> 0 | O39: =M39*N39 -> 0 | R39: =P39*Q39 -> 0 | U39: =S39*T39 -> 0 | X39: =V39*W39 -> 0
C40: =A40*B40 -> 0 | E40: =B40 -> 0 | F40: =D40*E40 -> 0 | I40: =G40*H40 -> 0 | L40: =J40*K40 -> 0 | O40: =M40*N40 -> 0 | R40: =P40*Q40 -> 0 | U40: =S40*T40 -> 0 | X40: =V40*W40 -> 0
C41: =A41*B41 -> 0 | E41: =B41 -> 0 | F41: =D41*E41 -> 0 | I41: =G41*H41 -> 0 | L41: =J41*K41 -> 0 | O41: =M41*N41 -> 0 | R41: =P41*Q41 -> 0 | U41: =S41*T41 -> 0 | X41: =V41*W41 -> 0
C42: =A42*B42 -> 0 | E42: =B42 -> 0 | F42: =D42*E42 -> 0 | I42: =G42*H42 -> 0 | L42: =J42*K42 -> 0 | O42: =M42*N42 -> 0 | R42: =P42*Q42 -> 0 | U42: =S42*T42 -> 0 | X42: =V42*W42 -> 0
C43: =A43*B43 -> 0 | E43: =B43 -> 0 | F43: =D43*E43 -> 0 | I43: =G43*H43 -> 0 | L43: =J43*K43 -> 0 | O43: =M43*N43 -> 0 | R43: =P43*Q43 -> 0 | U43: =S43*T43 -> 0 | X43: =V43*W43 -> 0
C44: =A44*B44 -> 0 | E44: =B44 -> 0 | F44: =D44*E44 -> 0 | I44: =G44*H44 -> 0 | L44: =J44*K44 -> 0 | O44: =M44*N44 -> 0 | R44: =P44*Q44 -> 0 | U44: =S44*T44 -> 0 | X44: =V44*W44 -> 0
C45: =A45*B45 -> 0 | E45: =B45 -> 0 | F45: =D45*E45 -> 0 | I45: =G45*H45 -> 0 | L45: =J45*K45 -> 0 | O45: =M45*N45 -> 0 | R45: =P45*Q45 -> 0 | U45: =S45*T45 -> 0 | X45: =V45*W45 -> 0
C46: =A46*B46 -> 0 | E46: =B46 -> 0 | F46: =D46*E46 -> 0
C47: =A47*B47 -> 0 | E47: =B47 -> 0 | F47: =D47*E47 -> 0 | I47: =G47*H47 -> 0 | L47: =J47*K47 -> 0 | O47: =M47*N47 -> 0 | R47: =P47*Q47 -> 0 | U47: =S47*T47 -> 0 | X47: =V47*W47 -> 0
C48: =A48*B48 -> 0 | E48: =B48 -> 0 | F48: =D48*E48 -> 0 | I48: =G48*H48 -> 0 | L48: =J48*K48 -> 0 | O48: =M48*N48 -> 0 | R48: =P48*Q48 -> 0 | U48: =S48*T48 -> 0 | X48: =V48*W48 -> 0
C49: =A49*B49 -> 0 | E49: =B49 -> 0 | F49: =D49*E49 -> 0 | I49: =G49*H49 -> 0 | L49: =J49*K49 -> 0 | O49: =M49*N49 -> 0 | R49: =P49*Q49 -> 0 | U49: =S49*T49 -> 0 | X49: =V49*W49 -> 0
C50: =A50*B50 -> 0 | E50: =B50 -> 0 | F50: =D50*E50 -> 0 | I50: =G50*H50 -> 0 | L50: =J50*K50 -> 0 | O50: =M50*N50 -> 0 | R50: =P50*Q50 -> 0 | U50: =S50*T50 -> 0 | X50: =V50*W50 -> 0
C51: =A51*B51 -> 0 | E51: =B51 -> 0 | F51: =D51*E51 -> 0 | I51: =G51*H51 -> 0 | L51: =J51*K51 -> 0 | O51: =M51*N51 -> 0 | R51: =P51*Q51 -> 0 | U51: =S51*T51 -> 0 | X51: =V51*W51 -> 0
C52: =A52*B52 -> 0 | E52: =B52 -> 0 | F52: =D52*E52 -> 0 | I52: =G52*H52 -> 0 | L52: =J52*K52 -> 0 | O52: =M52*N52 -> 0 | R52: =P52*Q52 -> 0 | U52: =S52*T52 -> 0 | X52: =V52*W52 -> 0
...

Sheet Dom
A1: PdV | B1: 0289 PAM PD ASPETTI | E1: data | G1: nr. Carico | M1: Tot. Val. Copertina Invio | O1: =+C6+I6+O6+U6 -> 0 | P1: Tot. Val. Copertina Reso | R1: =F6+L6+R6+X6 -> 0 | S1: Valore Carico Copertina | U1: =O1-R1 -> 0 | W1: Sett.
A2: 205 CHIMINELLI | G2: "Fornitore" | M2: "Fornitore" | S2: "Fornitore"
B3: n° copie | C3: TOTALE INVIO | E3: n° copie | F3: TOTALE RESO | H3: n° copie | I3: TOTALE INVIO | K3: n° copie | L3: TOTALE RESO | N3: n° copie | O3: TOTALE INVIO | Q3: n° copie | R3: TOTALE RESO | T3: n° copie | U3: TOTALE INVIO | W3: n° copie | X3: TOTALE RESO
A4: Q | B4: =SUM(A9:A33) -> 0 | C4: =SUM(C9:C33) -> 0 | D4: Q | E4: =SUM(D9:D33) -> 0 | F4: =SUM(F9:F33) -> 0 | G4: Q | H4: =SUM(G9:G33) -> 0 | I4: =SUM(I9:I33) -> 0 | J4: Q | K4: =SUM(J9:J33) -> 0 | L4: =SUM(L9:L33) -> 0 | M4: Q | N4: =SUM(M9:M33) -> 0 | O4: =SUM(O9:O33) -> 0 | P4: Q | Q4: =SUM(P9:P33) -> 0 | R4: =SUM(R9:R33) -> 0 | S4: Q | T4: =SUM(S9:S33) -> 0 | U4: =SUM(U9:U33) -> 0 | V4: Q | W4: =SUM(V9:V33) -> 0 | X4: =SUM(X9:X33) -> 0
A5: P | B5: =SUM(A36:A90) -> 0 | C5: =SUM(C36:C90) -> 0 | D5: P | E5: =SUM(D36:D90) -> 0 | F5: =SUM(F36:F90) -> 0 | G5: P | H5: =SUM(G36:G90) -> 0 | I5: =SUM(I36:I90) -> 0 | J5: P | K5: =SUM(J36:J90) -> 0 | L5: =SUM(L36:L90) -> 0 | M5: P | N5: =SUM(M36:M90) -> 0 | O5: =SUM(O36:O90) -> 0 | P5: P | Q5: =SUM(P36:P90) -> 0 | R5: =SUM(R36:R90) -> 0 | S5: P | T5: =SUM(S36:S90) -> 0 | U5: =SUM(U36:U90) -> 0 | V5: P | W5: =SUM(V36:V90) -> 0 | X5: =SUM(X36:X90) -> 0
C6: =SUM(C4:C5) -> 0 | F6: =SUM(F4:F5) -> 0 | I6: =SUM(I4:I5) -> 0 | L6: =SUM(L4:L5) -> 0 | O6: =SUM(O4:O5) -> 0 | R6: =SUM(R4:R5) -> 0 | U6: =SUM(U4:U5) -> 0 | X6: =SUM(X4:X5) -> 0
A7: INVIO QUOTIDIANI | D7: RESO QUOTIDIANI | G7: INVIO QUOTIDIANI | J7: RESO QUOTIDIANI | M7: INVIO QUOTIDIANI | P7: RESO QUOTIDIANI | S7: INVIO QUOTIDIANI | V7: RESO QUOTIDIANI
A8: Pezzi | B8: Prezzo | C8: TOTALE | D8: Pezzi | E8: Prezzo | F8: TOTALE | G8: Pezzi | H8: Prezzo | I8: TOTALE | J8: Pezzi | K8: Prezzo | L8: TOTALE | M8: Pezzi | N8: Prezzo | O8: TOTALE | P8: Pezzi | Q8: Prezzo | R8: TOTALE | S8: Pezzi | T8: Prezzo | U8: TOTALE | V8: Pezzi | W8: Prezzo | X8: TOTALE
C9: =A9*B9 -> 0 | F9: =D9*E9 -> 0 | I9: =G9*H9 -> 0 | L9: =J9*K9 -> 0 | O9: =M9*N9 -> 0 | R9: =P9*Q9 -> 0 | U9: =S9*T9 -> 0 | X9: =V9*W9 -> 0
C10: =A10*B10 -> 0 | F10: =D10*E10 -> 0 | I10: =G10*H10 -> 0 | L10: =J10*K10 -> 0 | O10: =M10*N10 -> 0 | R10: =P10*Q10 -> 0 | U10: =S10*T10 -> 0 | X10: =V10*W10 -> 0
C11: =A11*B11 -> 0 | F11: =D11*E11 -> 0 | I11: =G11*H11 -> 0 | L11: =J11*K11 -> 0 | O11: =M11*N11 -> 0 | R11: =P11*Q11 -> 0 | U11: =S11*T11 -> 0 | X11: =V11*W11 -> 0
C12: =A12*B12 -> 0 | F12: =D12*E12 -> 0 | I12: =G12*H12 -> 0 | L12: =J12*K12 -> 0 | O12: =M12*N12 -> 0 | R12: =P12*Q12 -> 0 | U12: =S12*T12 -> 0 | X12: =V12*W12 -> 0
C13: =A13*B13 -> 0 | F13: =D13*E13 -> 0 | I13: =G13*H13 -> 0 | L13: =J13*K13 -> 0 | O13: =M13*N13 -> 0 | R13: =P13*Q13 -> 0 | U13: =S13*T13 -> 0 | X13: =V13*W13 -> 0
C14: =A14*B14 -> 0 | F14: =D14*E14 -> 0 | I14: =G14*H14 -> 0 | L14: =J14*K14 -> 0 | O14: =M14*N14 -> 0 | R14: =P14*Q14 -> 0 | U14: =S14*T14 -> 0 | X14: =V14*W14 -> 0
C15: =A15*B15 -> 0 | F15: =D15*E15 -> 0 | I15: =G15*H15 -> 0 | L15: =J15*K15 -> 0 | O15: =M15*N15 -> 0 | R15: =P15*Q15 -> 0 | U15: =S15*T15 -> 0 | X15: =V15*W15 -> 0
C16: =A16*B16 -> 0 | F16: =D16*E16 -> 0 | I16: =G16*H16 -> 0 | L16: =J16*K16 -> 0 | O16: =M16*N16 -> 0 | R16: =P16*Q16 -> 0 | U16: =S16*T16 -> 0 | X16: =V16*W16 -> 0
C17: =A17*B17 -> 0 | F17: =D17*E17 -> 0 | I17: =G17*H17 -> 0 | L17: =J17*K17 -> 0 | O17: =M17*N17 -> 0 | R17: =P17*Q17 -> 0 | U17: =S17*T17 -> 0 | X17: =V17*W17 -> 0
C18: =A18*B18 -> 0 | F18: =D18*E18 -> 0 | I18: =G18*H18 -> 0 | L18: =J18*K18 -> 0 | O18: =M18*N18 -> 0 | R18: =P18*Q18 -> 0 | U18: =S18*T18 -> 0 | X18: =V18*W18 -> 0
C19: =A19*B19 -> 0 | F19: =D19*E19 -> 0 | I19: =G19*H19 -> 0 | L19: =J19*K19 -> 0 | O19: =M19*N19 -> 0 | R19: =P19*Q19 -> 0 | U19: =S19*T19 -> 0 | X19: =V19*W19 -> 0
C20: =A20*B20 -> 0 | F20: =D20*E20 -> 0 | I20: =G20*H20 -> 0 | L20: =J20*K20 -> 0 | O20: =M20*N20 -> 0 | R20: =P20*Q20 -> 0 | U20: =S20*T20 -> 0 | X20: =V20*W20 -> 0
... C33: =A33*B33 -> 0 | F33: =D33*E33 -> 0 | I33: =G33*H33 -> 0 | L33: =J33*K33 -> 0 | O33: =M33*N33 -> 0 | R33: =P33*Q33 -> 0 | U33: =S33*T33 -> 0 | X33: =V33*W33 -> 0
A34: INVIO RIVISTE | D34: RESO RIVISTE | G34: INVIO RIVISTE | J34: RESO RIVISTE | M34: INVIO RIVISTE | P34: RESO RIVISTE | S34: INVIO RIVISTE | V34: RESO RIVISTE
A35: Pezzi | B35: Prezzo | C35: TOTALE | D35: Pezzi | E35: Prezzo | F35: TOTALE | G35: Pezzi | H35: Prezzo | I35: TOTALE | J35: Pezzi | K35: Prezzo | L35: TOTALE | M35: Pezzi | N35: Prezzo | O35: TOTALE | P35: Pezzi | Q35: Prezzo | R35: TOTALE | S35: Pezzi | T35: Prezzo | U35: TOTALE | V35: Pezzi | W35: Prezzo | X35: TOTALE
C36: =A36*B36 -> 0 | F36: =D36*E36 -> 0 | I36: =G36*H36 -> 0 | L36: =J36*K36 -> 0 | O36: =M36*N36 -> 0 | R36: =P36*Q36 -> 0 | U36: =S36*T36 -> 0 | X36: =V36*W36 -> 0
C37: =A37*B37 -> 0 | F37: =D37*E37 -> 0 | I37: =G37*H37 -> 0 | L37: =J37*K37 -> 0 | O37: =M37*N37 -> 0 | R37: =P37*Q37 -> 0 | U37: =S37*T37 -> 0 | X37: =V37*W37 -> 0
C38: =A38*B38 -> 0 | F38: =D38*E38 -> 0 | I38: =G38*H38 -> 0 | L38: =J38*K38 -> 0 | O38: =M38*N38 -> 0 | R38: =P38*Q38 -> 0 | U38: =S38*T38 -> 0 | X38: =V38*W38 -> 0
C39: =A39*B39 -> 0 | F39: =D39*E39 -> 0 | I39: =G39*H39 -> 0 | L39: =J39*K39 -> 0 | O39: =M39*N39 -> 0 | R39: =P39*Q39 -> 0 | U39: =S39*T39 -> 0 | X39: =V39*W39 -> 0
C40: =A40*B40 -> 0 | F40: =D40*E40 -> 0 | I40: =G40*H40 -> 0 | L40: =J40*K40 -> 0 | O40: =M40*N40 -> 0 | R40: =P40*Q40 -> 0 | U40: =S40*T40 -> 0 | X40: =V40*W40 -> 0
C41: =A41*B41 -> 0 | F41: =D41*E41 -> 0 | I41: =G41*H41 -> 0 | L41: =J41*K41 -> 0 | O41: =M41*N41 -> 0 | R41: =P41*Q41 -> 0 | U41: =S41*T41 -> 0 | X41: =V41*W41 -> 0
C42: =A42*B42 -> 0 | F42: =D42*E42 -> 0 | I42: =G42*H42 -> 0 | L42: =J42*K42 -> 0 | O42: =M42*N42 -> 0 | R42: =P42*Q42 -> 0 | U42: =S42*T42 -> 0 | X42: =V42*W42 -> 0
C43: =A43*B43 -> 0 | F43: =D43*E43 -> 0 | I43: =G43*H43 -> 0 | L43: =J43*K43 -> 0 | O43: =M43*N43 -> 0 | R43: =P43*Q43 -> 0 | U43: =S43*T43 -> 0 | X43: =V43*W43 -> 0
C44: =A44*B44 -> 0 | F44: =D44*E44 -> 0 | I44: =G44*H44 -> 0 | L44: =J44*K44 -> 0 | O44: =M44*N44 -> 0 | R44: =P44*Q44 -> 0 | U44: =S44*T44 -> 0 | X44: =V44*W44 -> 0
C45: =A45*B45 -> 0 | F45: =D45*E45 -> 0 | I45: =G45*H45 -> 0 | L45: =J45*K45 -> 0 | O45: =M45*N45 -> 0 | R45: =P45*Q45 -> 0 | U45: =S45*T45 -> 0 | X45: =V45*W45 -> 0
C46: =A46*B46 -> 0 | F46: =D46*E46 -> 0 | I46: =G46*H46 -> 0 | L46: =J46*K46 -> 0 | O46: =M46*N46 -> 0 | R46: =P46*Q46 -> 0 | U46: =S46*T46 -> 0 | X46: =V46*W46 -> 0
C47: =A47*B47 -> 0 | F47: =D47*E47 -> 0 | I47: =G47*H47 -> 0 | L47: =J47*K47 -> 0 | O47: =M47*N47 -> 0 | R47: =P47*Q47 -> 0 | U47: =S47*T47 -> 0 | X47: =V47*W47 -> 0
... C90: =A90*B90 -> 0 | F90: =D90*E90 -> 0 | I90: =G90*H90 -> 0 | L90: =J90*K90 -> 0 | O90: =M90*N90 -> 0 | R90: =P90*Q90 -> 0 | U90: =S90*T90 -> 0 | X90: =V90*W90 -> 0
A93: Q | B93: Quotidiani
A94: P | B94: Riviste

Sheet Sett
A2: PdV | B2: =Lun!$B$1 -> 0289 PAM PD ASPETTI | D2: Sett. | E2: =Lun!$X$1 -> 2
A3: data | B3: nr. Carico | C3: Totale Valore Copertina Invio | D3: Totale Valore Copertina Reso | E3: Valore Copertina Carico | F3: Valore Panorama (sc. 9,70%) Carico
A4: =Lun!F$1 -> 46027 | B4: =Lun!I1 -> 283 | C4: =Lun!O$1 -> 20.4 | D4: =Lun!R$1 -> 4.8 | E4: =Lun!U$1 -> 15.6 | F4: =E4*0.903 -> 14.0868
A5: =Mar!F$1 -> 46028 | B5: =Mar!I1 -> 284 | C5: =Mar!O$1 -> 0 | D5: =Mar!R$1 -> 0 | E5: =Mar!U$1 -> 0 | F5: =E5*0.903 -> 0
A6: =Mer!F$1 -> 46029 | B6: =Mer!I1 -> 285 | C6: =Mer!O$1 -> 0 | D6: =Mer!R$1 -> 0 | E6: =Mer!U$1 -> 0 | F6: =E6*0.903 -> 0
A7: =Gio!F$1 -> 46030 | B7: =Gio!I1 -> 286 | C7: =Gio!O$1 -> 0 | D7: =Gio!R$1 -> 0 | E7: =Gio!U$1 -> 0 | F7: =E7*0.903 -> 0
A8: =Ven!F$1 -> 46031 | B8: =Ven!I1 -> 287 | C8: =Ven!O$1 -> 0 | D8: =Ven!R$1 -> 0 | E8: =Ven!U$1 -> 0 | F8: =E8*0.903 -> 0
A9: =Sab!F$1 -> 46032 | B9: =Sab!I1 -> 282 | C9: =Sab!O$1 -> 0 | D9: =Sab!R$1 -> 0 | E9: =Sab!U$1 -> 0 | F9: =E9*0.903 -> 0
A10: =Dom!F$1 -> 0 | B10: =Dom!I1 -> 0 | C10: =Dom!O$1 -> 0 | D10: =Dom!R$1 -> 0 | E10: =Dom!U$1 -> 0 | F10: =E10*0.903 -> 0
B11: totale settimana | C11: =SUM(C4:C10) -> 20.4 | D11: =SUM(D4:D10) -> 4.8 | E11: =C11-D11 -> 15.6 | F11: =SUM(F4:F10) -> 14.0868

Sheet Foglio1
A2: PdV | B2: =Lun!$B$1 -> 0289 PAM PD ASPETTI | D2: Sett. | E2: =Lun!$X$1 -> 2
A3: data | B3: nr. Carico | C3: Totale Valore Copertina Invio | D3: Totale Valore Copertina Reso | E3: Valore Copertina Carico | F3: Valore Panorama (sc. 7,80%) Carico
A4: =Lun!F$1 -> 46027 | B4: =Lun!I1 -> 283 | C4: =Lun!O$1 -> 20.4 | D4: =Lun!R$1 -> 4.8 | E4: =Lun!U$1 -> 15.6 | F4: =E4*0.922 -> 14.3832
A5: =Mar!F$1 -> 46028 | B5: =Mar!I1 -> 284 | C5: =Mar!O$1 -> 0 | D5: =Mar!R$1 -> 0 | E5: =Mar!U$1 -> 0 | F5: =E5*0.922 -> 0
A6: =Mer!F$1 -> 46029 | B6: =Mer!I1 -> 285 | C6: =Mer!O$1 -> 0 | D6: =Mer!R$1 -> 0 | E6: =Mer!U$1 -> 0 | F6: =E6*0.922 -> 0
A7: =Gio!F$1 -> 46030 | B7: =Gio!I1 -> 286 | C7: =Gio!O$1 -> 0 | D7: =Gio!R$1 -> 0 | E7: =Gio!U$1 -> 0 | F7: =E7*0.922 -> 0
A8: =Ven!F$1 -> 46031 | B8: =Ven!I1 -> 287 | C8: =Ven!O$1 -> 0 | D8: =Ven!R$1 -> 0 | E8: =Ven!U$1 -> 0 | F8: =E8*0.922 -> 0
A9: =Sab!F$1 -> 46032 | B9: =Sab!I1 -> 282 | C9: =Sab!O$1 -> 0 | D9: =Sab!R$1 -> 0 | E9: =Sab!U$1 -> 0 | F9: =E9*0.922 -> 0
A10: =Dom!F$1 -> 0 | B10: =Dom!I1 -> 0 | C10: =Dom!O$1 -> 0 | D10: =Dom!R$1 -> 0 | E10: =Dom!U$1 -> 0 | F10: =E10*0.922 -> 0
B11: totale settimana | C11: =SUM(C4:C10) -> 20.4 | D11: =SUM(D4:D10) -> 4.8 | E11: =C11-D11 -> 15.6 | F11: =SUM(F4:F10) -> 14.3832

Sheet FOGLIO GDMS
A1: PDV | B1: data | C1: DL | D1: Totale Valore Copertina Invio | E1: Totale Valore Copertina Reso
A2: =+Lun!B$1 -> 0289 PAM PD ASPETTI | B2: =+Lun!F$1 -> 46027 | C2: =+Lun!A2 -> 205 CHIMINELLI | D2: =+Lun!C6 -> 20.4 | E2: =+Lun!F6 -> 4.8
A3: =+Lun!B$1 -> 0289 PAM PD ASPETTI | B3: =+Lun!F$1 -> 46027 | C3: =+Lun!G2 -> "Fornitore" | D3: =+Lun!I6 -> 0 | E3: =+Lun!L6 -> 0
A4: =+Lun!B$1 -> 0289 PAM PD ASPETTI | B4: =+Lun!F$1 -> 46027 | C4: =+Lun!M2 -> "Fornitore" | D4: =+Lun!O6 -> 0 | E4: =+Lun!R6 -> 0
A5: =+Mar!B$1 -> 0289 PAM PD ASPETTI | B5: =+Mar!F$1 -> 46028 | C5: =+Mar!A2 -> 205 CHIMINELLI | D5: =+Mar!C6 -> 0 | E5: =+Mar!F6 -> 0
A6: =+Mar!B$1 -> 0289 PAM PD ASPETTI | B6: =+Mar!F$1 -> 46028 | C6: =+Mar!G2 -> "Fornitore" | D6: =+Mar!I6 -> 0 | E6: =+Mar!L6 -> 0
A7: =+Mar!B$1 -> 0289 PAM PD ASPETTI | B7: =+Mar!F$1 -> 46028 | C7: =+Mar!M2 -> "Fornitore" | D7: =+Mar!O6 -> 0 | E7: =+Mar!R6 -> 0
A8: =+Mer!B$1 -> 0289 PAM PD ASPETTI | B8: =+Mer!F$1 -> 46029 | C8: =+Mer!A2 -> 205 CHIMINELLI | D8: =+Mer!C6 -> 0 | E8: =+Mer!F6 -> 0
A9: =+Mer!B$1 -> 0289 PAM PD ASPETTI | B9: =+Mer!F$1 -> 46029 | C9: =+Mer!G2 -> "Fornitore" | D9: =+Mer!I6 -> 0 | E9: =+Mer!L6 -> 0
A10: =+Mer!B$1 -> 0289 PAM PD ASPETTI | B10: =+Mer!F$1 -> 46029 | C10: =+Mer!M2 -> "Fornitore" | D10: =+Mer!O6 -> 0 | E10: =+Mer!R6 -> 0
A11: =+Gio!B$1 -> 0289 PAM PD ASPETTI | B11: =+Gio!F$1 -> 46030 | C11: =+Gio!A2 -> 205 CHIMINELLI | D11: =+Gio!C6 -> 0 | E11: =+Gio!F6 -> 0
A12: =+Gio!B$1 -> 0289 PAM PD ASPETTI | B12: =+Gio!F$1 -> 46030 | C12: =+Gio!G2 -> "Fornitore" | D12: =+Gio!I6 -> 0 | E12: =+Gio!L6 -> 0
A13: =+Gio!B$1 -> 0289 PAM PD ASPETTI | B13: =+Gio!F$1 -> 46030 | C13: =+Gio!M2 -> "Fornitore" | D13: =+Gio!O6 -> 0 | E13: =+Gio!R6 -> 0
A14: =+Ven!B$1 -> 0289 PAM PD ASPETTI | B14: =+Ven!F$1 -> 46031 | C14: =+Ven!A2 -> 205 CHIMINELLI | D14: =+Ven!C6 -> 0 | E14: =+Ven!F6 -> 0
A15: =+Ven!B$1 -> 0289 PAM PD ASPETTI | B15: =+Ven!F$1 -> 46031 | C15: =+Ven!G2 -> "Fornitore" | D15: =+Ven!I6 -> 0 | E15: =+Ven!L6 -> 0
A16: =+Ven!B$1 -> 0289 PAM PD ASPETTI | B16: =+Ven!F$1 -> 46031 | C16: =+Ven!M2 -> "Fornitore" | D16: =+Ven!O6 -> 0 | E16: =+Ven!R6 -> 0
A17: =+Sab!B$1 -> 0289 PAM PD ASPETTI | B17: =+Sab!F$1 -> 46032 | C17: =+Sab!A2 -> 205 CHIMINELLI | D17: =+Sab!C6 -> 0 | E17: =+Sab!F6 -> 0
